Workbook
Name a1j: [1]HVac_SimulationStatus!$AJ$302

Sheet DATA TRANSFER
D2: 0
A3: GUI Screen (CPU_WS-CPU_CAB/PTT)
J6: =IF('Mode Logic'!C18>'Mode Logic'!G5,1,0)
G7: ='CIRCUIT SIM'!J4
A8: HVAC-Control Panel Screen | S8: HVAC- Operating Mode Screen | AH8: HVAC-: 2D Schematic Screen | BE8: Ethernet Architecture Screen | BV8: Representative Operational Graph | DK8: GUI Driver Panel
A9: SR NO | B9: Component_ID | C9: INPUT | D9: ='LFD New'!D2 | E9: Source | F9: Value | G9: Remark | H9: SR NO | I9: Component_ID | J9: OUTPUT | K9: Data Type | L9: Source | M9: Value | N9: Remark | Q9: =IF('Mode Logic'!P18=1,5,0) | S9: SR NO | T9: Component_ID | U9: INPUT | V9: Data Type | W9: Source | X9: Value | Y9: Remark | Z9: SR NO | AA9: Component_ID | AB9: OUTPUT | AC9: Data Type | AD9: Source | AE9: Value | AF9: Remark | AH9: SR NO | AI9: Component_ID | AJ9: INPUT | AK9: Data Type | AL9: Source | AM9: Value | AN9: Remark | AO9: SR NO | AP9: Component_ID | AQ9: OUTPUT | AR9: Data Type | AS9: Source | AT9: Value | AU9: Remark | BE9: SR NO | BF9: Component_ID | BG9: INPUT | BH9: Data Type | BI9: Source | BJ9: Value | BK9: Remark | BL9: SR NO | BM9: Component_ID | BN9: OUTPUT | BO9: Data Type | BP9: Source | BQ9: Value | BR9: Remark | BV9: SR NO | BW9: Component_ID | BX9: INPUT | BY9: Data Type | BZ9: Source | CA9: Value | CB9: Remark | CC9: SR NO | CD9: Component_ID | CE9: OUTPUT | CF9: Data Type | CG9: Source | CH9: Value | CI9: Remark | CK9: SR NO | CL9: Component_ID | CM9: INPUT | CN9: Data Type | CO9: Source | CP9: Value | CQ9: Remark | CU9: SR NO | CV9: Component_ID | CW9: OUTPUT | CX9: Data Type | CY9: Source | CZ9: Value | DA9: Remark | DK9: SR NO | DL9: Description | DM9: INPUT | DN9: Data Type | DO9: Source | DP9: Value | DQ9: Remark
A10: 1 | B10: HVAC1_CBF_1 | C10: Cab Booster Fan | D10: Boolean | F10: 0 | H10: 18 | I10: HVAC1_ISA_ON_1 | J10: Internal Smoke Alarm ON | K10: Boolean | L10: HVAC I/Os_DO | M10: =F28 | U10: Spare | X10: 0 | Z10: 1 | AA10: HVAC1_AMB_TEMP_1 | AB10: Ambient Temperature | AC10: Float | AE10: =F39 | AM10: 0 | AO10: 1 | AP10: HVAC1_ACCESS_VALVE_1 | AQ10: Access Valve_1 | AR10: Boolean | AT10: 1 | BJ10: 0 | BL10: 1 | BM10: TCMS_CN1 | BN10: TCMS(CN1) | BO10: Boolean | BQ10: 1 | CA10: 0 | CC10: 1 | CD10: AVG_TEMPERATURE_C_ | CE10: Average Temperature[°C](Y axis) | CF10: Float | CH10: =Calculation!B34 | CI10: =Calculation!B34 | CM10: Fault information (Text 48–55) | DE10: Reduced Mode | DK10: 1 | DL10: Key Switch On | DN10: 0/1 | DO10: GUI | DP10: 1
A11: 2 | B11: HVAC1_PWR_DS3D_1 | C11: Power DS3D | D11: Boolean | F11: 0 | H11: 19 | I11: HVAC1_ISA_OFF_1 | J11: =IF('Mode Logic'!P18=1,100,0) | K11: Boolean | L11: HVAC I/Os_DO | M11: =IF(NOT(M10),1,0) | U11: Spare | X11: 0 | Z11: 2 | AA11: HVAC1_RET_AIR_TEMP_1 | AB11: Return Air Temperature | AC11: Float | AE11: =Calculation!B36 | AM11: 0 | AO11: 2 | AP11: HVAC1_DRIER_FILTER_1 | AQ11: Drier Filter_1 | AR11: Boolean | AT11: 1 | BJ11: 0 | BL11: 2 | BM11: TCMS_CN2 | BN11: TCMS(CN2) | BO11: Boolean | BQ11: 0 | CA11: 0 | CC11: 2 | CD11: HOUR_OF_DAY | CE11: Set Point Temperature | CF11: Float | CH11: =Calculation!B33 | CM11: HighPressureSwitch1 (Text 49, Bit 0) | DE11: Emergency Vent Mode | DK11: =DK10+1 | DL11: Off | DN11: 0/1 | DO11: GUI | DP11: 0
A12: 3 | B12: HVAC1_DOP_1 | C12: Door Operation- OPEN + Close | D12: Boolean | F12: 1 | H12: 20 | I12: HVAC1_ESA_ON_1 | J12: Extenal Smoke Alarm ON | K12: Boolean | L12: HVAC I/Os_DO | M12: =F29 | U12: Spare | X12: 0 | Z12: 3 | AA12: HVAC1_REL_HUM_1 | AB12: Relative Humidity | AC12: Float | AE12: =F43 | AM12: 0 | AO12: 3 | AP12: HVAC1_CONDENSER_COIL_1 | AQ12: Condenser Coil_1 | AR12: Boolean | AT12: 1 | BJ12: 0 | BL12: 3 | BM12: HVAC1 | BN12: HVAC1 | BO12: Boolean | BQ12: 1 | CA12: 0 | CE12: New RAT | CH12: =Calculation!B35 | CM12: LowPressureSwitch1 (Text 49, Bit 1) | DE12: Open door | DK12: =DK11+1 | DL12: Rev | DN12: 0/1 | DO12: GUI | DP12: 0
A13: 5 | B13: HVAC1_RAT_ST_1 | C13: RAT START | D13: Boolean | F13: 0 | H13: 21 | I13: HVAC1_ESA_OFF_1 | J13: Extenal Smoke Alarm OFF | K13: Boolean | L13: HVAC I/Os_DO | M13: =IF(NOT(M12),1,0) | U13: Spare | X13: 0 | Z13: 4 | AA13: HVAC1_FRESH_AIR_DAMP_1 | AB13: Fresh Air Damper | AC13: Float | AE13: =IF('Mode Logic'!P18=1,100,0) | AM13: 0 | AO13: 4 | AP13: HVAC1_CHECK_VALVE_1 | AQ13: Check Valves_1 | AR13: Boolean | AT13: 1 | BJ13: 0 | BL13: 4 | BM13: HVAC2 | BN13: HVAC2 | BO13: Boolean | BQ13: 1 | CA13: 0 | CE13: Initial RAT | CH13: =F38 | CM13: Car ID / HVAC Unit Identification | DE13: Read for RAT Loop | DF13: =Calculation!I51 | DG13: =Calculation!J51 | DH13: =Calculation!K51 | DK13: =DK12+1 | DL13: Standby | DN13: 0/1 | DO13: GUI | DP13: 0
A14: 6 | B14: HVAC1_SPT_INC_1 | C14: Set Point Tempaerature °C Increment(+) | D14: Float | H14: 22 | I14: HVAC1_RAD_ON_1 | J14: Return Air Damper ON | K14: Boolean | L14: HVAC I/Os_DO | M14: ='Mode Logic'!Q18 | U14: Spare | X14: 0 | Z14: 5 | AA14: HVAC_Set Point Temperature | AB14: Set Point Temperature | AC14: Float | AE14: =F37 | AM14: 1 | AO14: 5 | AP14: HVAC1_CONDENSER_FAN_1 | AQ14: Condenser Fan_1 | AR14: Boolean | AT14: ='Mode Logic'!S18 | BJ14: 0 | BQ14: 0 | CA14: 0 | CE14: Spare | CH14: 0 | CM14: HVAC SD: ON (Text 35, Bit 0) | DE14: Write for RAT Loop | DF14: 0 | DG14: 1 | DH14: 1 | DK14: =DK13+1 | DL14: Fwd | DN14: 0/1 | DO14: GUI | DP14: 0
A15: 7 | B15: ='LFD New'!D2 | C15: Set Point Tempaerature °C Decrement(-) | D15: Float | H15: 23 | I15: HVAC1_RAD_OFF_1 | J15: Return Air Damper OFF | K15: Boolean | L15: HVAC I/Os_DO | M15: =IF(NOT(M14),1,0) | U15: Spare | X15: 0 | Z15: 6 | AA15: HVAC1_SMOKE_OUTSIDE_1 | AB15: Smoke Outside | AC15: Boolean | AE15: =AE27 | AM15: 1 | AO15: 6 | AP15: HVAC1_COMPRESSOR_1 | AQ15: Compressors_1 | AR15: Boolean | AT15: ='Mode Logic'!L18 | BJ15: 0 | BQ15: 0 | CA15: 0 | CE15: Spare | CH15: 0 | CM15: Heater Thermostat 1 & 2 (Text 51, Bits 1–2) | DE15: RAT Loop ON | DF15: 1 | DG15: 1 | DH15: 1 | DK15: =DK14+1 | DL15: Atp | DN15: 0/1 | DO15: GUI | DP15: 1
A16: 8 | B16: HVAC1_RAT_INC_1 | C16: Return Air Tempaerature °C Increment(+) | D16: ='LFD New'!D18 | H16: 24 | I16: HVAC1_FAD_ON_1 | J16: Fresh Air Damper ON | K16: Boolean | L16: HVAC I/Os_DO | M16: ='Mode Logic'!P18 | U16: Spare | X16: 0 | Z16: 7 | AA16: HVAC1_FAULT_MODE_1 | AB16: Fault Mode | AC16: Boolean | AE16: 1 | AM16: 0 | AO16: 7 | AP16: HVAC1_LIQUID_LINE_SOLENOID_VALVE_1 | AQ16: Liquid Line Solenoid Valve_1 | AR16: Boolean | AT16: 1 | BJ16: 0 | BQ16: 0 | CA16: 0 | CE16: Spare | CH16: 0 | CM16: LowPressureSwitch2 (Text 49, Bit 3) | DK16: =DK15+1 | DL16: Ato | DN16: 0/1 | DO16: GUI | DP16: 0
A17: 9 | B17: HVAC1_RAT_DEC_1 | C17: Return Air Tempaerature °C Decrement(-) | D17: Float | H17: 25 | I17: HVAC1_FAD_OFF_1 | J17: Fresh Air Damper OFF | K17: Boolean | L17: HVAC I/Os_DO | M17: =IF(NOT(M16),1,0) | U17: =IF(OR('Mode Logic'!J3,'Mode Logic'!J4),1,0) | X17: 0 | Z17: 8 | AA17: =_xlfn.CONCAT("HVAC_",AB17) | AB17: Preconditioning: Preheating | AC17: Boolean | AE17: ='Mode Logic'!J3 | AM17: 0 | AO17: 8 | AP17: HVAC1_SIGHT_GLASS_1 | AQ17: Sight Glass_1 | AR17: Boolean | AT17: 1 | BJ17: 0 | BQ17: 0 | CA17: 0 | CE17: Spare | CH17: 0 | CM17: HighPressureSwitch2 (Text 49, Bit 2) | DK17: =DK16+1 | DL17: Mastercontroller in Braking | DN17: 0/1 | DO17: GUI
A18: 10 | B18: HVAC1_AMB_INC_1 | C18: ='Mode Logic'!J6 | D18: ='LFD New'!D20 | H18: 26 | I18: HVAC1_COMP_ST_ON_1 | J18: Compressor Status ON | K18: Boolean | M18: ='Mode Logic'!L18 | U18: Spare | X18: 0 | Z18: 9 | AA18: =_xlfn.CONCAT("HVAC_",AB18) | AB18: Preconditioning: Precooling | AC18: Boolean | AE18: ='Mode Logic'!J4 | AM18: 0 | AO18: 9 | AP18: HVAC1_ELECTRIC_HEATER_1 | AQ18: Electric Heater_1 | AR18: Boolean | AT18: ='Mode Logic'!R18 | BJ18: 0 | BQ18: 0 | CA18: 0 | CE18: Spare | CH18: 0 | CM18: SMDR (Smoke Detector Relay) (Text 56, Bit 0) | DK18: =DK17+1 | DL18: Mastercontroller in OFF | DN18: 0/1 | DO18: GUI
A19: 11 | B19: HVAC1_AMB_DEC_1 | C19: Ambient Tempaerature °C Decrement(-) | D19: Float | H19: 27 | I19: HVAC1_COMP_ST_OFF_1 | J19: Compressor Status OFF | K19: Boolean | M19: =IF(NOT(M18),1,0) | T19: ='Mode Logic'!S18 | U19: Spare | X19: 0 | Z19: 10 | AA19: =_xlfn.CONCAT("HVAC_",AB19) | AB19: Standard Automatic Cooling State 1 (Cooling Circuits Disabled) | AC19: Boolean | AE19: ='Mode Logic'!J6 | AM19: 0 | AO19: 10 | AP19: HVAC1_EVAP_FAN_MOTOR_1 | AQ19: Evaporator Fan Motor_1 | AR19: Boolean | AT19: ='Mode Logic'!U18 | BJ19: 0 | BQ19: 0 | CA19: 0 | CE19: Spare | CH19: 0 | CM19: Internal Fire Detection Signal (Hard-wired) | DK19: =DK18+1 | DL19: Mastercontroller in Powering | DN19: 0/1 | DO19: GUI
A20: 12 | B20: HVAC1_PL_INC_1 | C20: Passenget Load Increment(+) | D20: Integer | H20: 28 | I20: HVAC1_CF_ST_ON_1 | J20: Condenser Fan Status ON | K20: Boolean | M20: =IF(OR(AT14,AT22),1,0) | U20: Spare | X20: 0 | Z20: 11 | AA20: =_xlfn.CONCAT("HVAC_",AB20) | AB20: Standard Automatic Cooling State 2 (Up to 25% Modulated Cooling) | AC20: Boolean | AE20: ='Mode Logic'!J7 | AF20: =IF(AND('LFD OLD'!I6,'DATA TRANSFER'!AF21=0,AF22=0,AF24=0),1,0) | AM20: 0 | AO20: 11 | AP20: HVAC1_TXV_1 | AQ20: Thermal Expansion Valve_1 | AR20: Boolean | AT20: 1 | BJ20: 0 | BQ20: 0 | CA20: 0 | CE20: Spare | CH20: 0 | CM20: On-board Test 02: Cooling (5 mins) | DK20: =DK19+1 | DL20: Washer Push Button (Wpb) | DN20: 0/1 | DO20: GUI
A21: 13 | B21: HVAC1_PL_DEC_1 | C21: Passenget Load Decremen(-) | D21: Integer | H21: 29 | I21: HVAC1_CF_ST_OFF_1 | J21: Condenser Fan Status OFF | K21: Boolean | M21: =IF(NOT(M20),1,0) | U21: Spare | X21: 0 | Z21: 12 | AA21: =_xlfn.CONCAT("HVAC_",AB21) | AB21: Standard Automatic Cooling State 3 (Up to 50% Modulated Cooling) | AC21: Boolean | AE21: ='Mode Logic'!J8 | AM21: 0 | AO21: 12 | AP21: HVAC1_EVAPORATOR_COIL_1 | AQ21: Evaporator Coil_1 | AR21: Boolean | AT21: 1 | BJ21: 0 | BQ21: 0 | CA21: 0 | CE21: Spare | CH21: 0 | CM21: On-board Test 05: Heating (5 mins) | DK21: =DK20+1 | DL21: Air Horn High Button (Ahhb) | DN21: 0/1 | DO21: GUI
A22: 14 | B22: ='LFD New'!D25 | C22: Start Time Increment(+) | D22: Float | H22: 30 | I22: HVAC1_EF_ST_ON_1 | J22: Evaportor Fan Status ON | K22: Boolean | M22: =IF(OR(AT19,AT26),1,0) | U22: Spare | X22: 0 | Z22: 13 | AA22: =_xlfn.CONCAT("HVAC_",AB22) | AB22: Standard Automatic Cooling State 4 (Up to 75% Modulated Cooling) | AC22: Boolean | AE22: ='Mode Logic'!J9 | AM22: 0 | AO22: 13 | AP22: HVAC1_CONDENSER_FAN_2 | AQ22: Condenser Fan_2 | AR22: Boolean | AT22: ='Mode Logic'!T18 | BJ22: 0 | BQ22: 0 | CA22: 0 | CE22: Spare | CH22: 0 | CM22: On-board Test 01: Ventilation (7 mins) | DK22: =DK21+1 | DL22: Call On Button (Colb) Maintained Pb Red | DN22: 0/1 | DO22: GUI
A23: 15 | B23: HVAC1_ST_DEC_1 | C23: Start Time Decrement(-) | D23: ='LFD New'!D25 | H23: 31 | I23: HVAC1_EF_ST_OFF_1 | J23: Evaportor Fan Status OFF | K23: Boolean | M23: =IF(NOT(M22),1,0) | U23: Spare | X23: 0 | Z23: 14 | AA23: =_xlfn.CONCAT("HVAC_",AB23) | AB23: Standard Automatic Cooling State 5 (Up to 100% Modulated Cooling) | AC23: Boolean | AE23: ='Mode Logic'!J10 | AM23: 0 | AO23: 14 | AP23: HVAC1_COMPRESSOR_2 | AQ23: Compressors_2 | AR23: Boolean | AT23: ='Mode Logic'!M18 | BJ23: 0 | BQ23: 0 | CA23: 0 | CE23: Spare | CH23: 0 | CM23: Staggered Start Sequence / Start Allow | CP23: 1 | DK23: =DK22+1 | DL23: Atb/Ato Start Button(Pbs) | DN23: 0/1 | DO23: GUI
A24: 16 | B24: HVAC1_CT_INC_1 | C24: Current Time Increment(+) | D24: Float | H24: 32 | I24: HVAC1_HTR_ST_ON_1 | J24: Heater Staus ON | K24: Boolean | M24: ='Mode Logic'!R18 | U24: Spare | X24: 0 | Z24: 15 | AA24: =_xlfn.CONCAT("HVAC_",AB24) | AB24: Ventilation Mode | AC24: Boolean | AE24: ='Mode Logic'!J11 | AM24: 0 | AO24: 15 | AP24: HVAC1_COMPRESSOR_3 | AQ24: Compressors_3 | AR24: Boolean | AT24: ='Mode Logic'!N18 | BJ24: 0 | BQ24: 0 | CA24: 0 | CE24: Spare | CH24: 0 | CM24: UTC Time (Seconds from 01/01/1970) | DK24: =DK23+1 | DL24: Right Door Open Button 1(Rdob1) | DN24: 0/1 | DO24: GUI
A25: 17 | B25: HVAC1_CT_DEC_1 | C25: Current Time Decrement(+) | D25: Float | H25: 33 | I25: HVAC1_HTR_ST_OFF_1 | J25: Heater Staus OFF | K25: Boolean | M25: =IF(NOT(M24),1,0) | U25: Spare | X25: 0 | Z25: 16 | AA25: =_xlfn.CONCAT("HVAC_",AB25) | AB25: Heating Mode | AC25: Boolean | AE25: ='Mode Logic'!J12 | AM25: 0 | AO25: 16 | AP25: HVAC1_COMPRESSOR_4 | AQ25: Compressors_4 | AR25: Boolean | AT25: ='Mode Logic'!O18 | BJ25: 0 | BQ25: 0 | CA25: 0 | CE25: Spare | CH25: 0 | CM25: LLV (Liquid Line Valve) Management | DK25: =DK24+1 | DL25: RDCB 1 | DN25: 0/1 | DO25: GUI
A26: 18 | B26: HVAC1_Hum | C26: Humidity Increment | D26: Float | H26: 34 | I26: HVAC1_COMP_1 | J26: Compressor 1 | K26: Boolean | M26: ='Mode Logic'!L18 | U26: Spare | V26: Float | X26: 0 | Z26: 17 | AA26: =_xlfn.CONCAT("HVAC_",AB26) | AB26: Internal Smoke Mode | AC26: Boolean | AE26: ='Mode Logic'!J13 | AJ26: Spare | AK26: Float | AM26: 0 | AO26: 17 | AP26: HVAC1_EVAP_FAN_MOTOR_2 | AQ26: Evaporator Fan Motor_2 | AR26: Boolean | AT26: ='Mode Logic'!V18 | BG26: Spare | BH26: Float | BJ26: 0 | BN26: Spare | BO26: Float | BQ26: 0 | BX26: Spare | BY26: Float | CA26: 0 | CE26: Spare | CF26: Float | CH26: 0 | CM26: Compressor Staggered Management Logic | DK26: =DK25+1 | DL26: Left Door Close Button 1(Ldcb1) | DN26: 0/1 | DO26: GUI
A27: 19 | B27: HVAC1_HU_DC | C27: Humidity Decrement | D27: Float | H27: 35 | I27: HVAC1_COMP_2 | J27: Compressor 2 | K27: Boolean | M27: ='Mode Logic'!M18 | U27: Spare | V27: Float | X27: 0 | Z27: 18 | AA27: =_xlfn.CONCAT("HVAC_",AB27) | AB27: External Smoke Mode | AC27: Boolean | AE27: ='Mode Logic'!J14 | AJ27: Spare | AK27: Float | AM27: 0 | AO27: 18 | AP27: HVAC1_ACCESS_VALVE_2 | AQ27: Access Valve_2 | AR27: Boolean | AT27: 1 | BG27: Spare | BH27: Float | BJ27: 0 | BN27: Spare | BO27: Float | BQ27: 0 | BX27: Spare | BY27: Float | CA27: 0 | CE27: Spare | CF27: Float | CH27: 0 | CM27: LPCO1 / LPCO2 (Refrigerant Low Pressure Fault) | DK27: =DK26+1 | DL27: LDOB1 | DN27: 0/1 | DO27: GUI
A28: 18 | B28: HVAC1_INT_SM | C28: Internal Smoke Sensor | D28: Boolean | F28: 0 | H28: 36 | I28: HVAC1_COMP_3 | J28: Compressor 3 | K28: Boolean | M28: ='Mode Logic'!N18 | U28: Spare | V28: Float | X28: 0 | Z28: 19 | AA28: =_xlfn.CONCAT("HVAC_",AB28) | AB28: Emergency Ventilation Mode | AC28: Boolean | AE28: ='Mode Logic'!J15 | AJ28: Spare | AK28: Float | AM28: 0 | AO28: 19 | AP28: HVAC1_DRIER_FILTER_2 | AQ28: Drier Filter_2 | AR28: Boolean | AT28: 1 | BG28: Spare | BH28: Float | BJ28: 0 | BN28: Spare | BO28: Float | BQ28: 0 | BX28: Spare | BY28: Float | CA28: 0 | CE28: Spare | CF28: Float | CH28: 0 | CM28: HEC Start Allow Delay (12s interval) | DK28: =DK27+1 | DL28: Run On Sight Button(Rospb) | DN28: 0/1 | DO28: GUI
A29: 19 | B29: HVAC1_EXT_SM | C29: External Smoke Sensor | D29: Boolean | F29: 1 | H29: 37 | I29: HVAC1_COMP_4 | J29: Compressor 4 | K29: Boolean | M29: ='Mode Logic'!O18 | U29: Spare | V29: Float | X29: 0 | Z29: 20 | AA29: HVAC1_SMOKE_INSIDE_1 | AB29: Smoke Inside | AC29: Boolean | AE29: =AE26 | AJ29: Spare | AK29: Float | AM29: 0 | AO29: 20 | AP29: HVAC1_CONDENSER_COIL_2 | AQ29: Condenser Coil_2 | AR29: Boolean | AT29: 1 | BG29: Spare | BH29: Float | BJ29: 0 | BN29: Spare | BO29: Float | BQ29: 0 | BX29: Spare | BY29: Float | CA29: 0 | CE29: Spare | CF29: Float | CH29: 0 | CM29: HEC Staggering Logic (0.5s–1s delay) | DK29: =DK28+1 | DL29: Lamp Test Button(Pls) | DN29: 0/1 | DO29: GUI
A30: 20 | B30: HVAC1_RM | C30: Reduced Mode | D30: Boolean | F30: 0 | H30: 38 | K30: Float | U30: Spare | V30: Float | X30: 0 | Z30: 21 | AC30: Float | AJ30: Spare | AK30: Float | AM30: 0 | AO30: 21 | AP30: HVAC1_CHECK_VALVE_2 | AQ30: Check Valves_2 | AR30: Boolean | AT30: 1 | BG30: Spare | BH30: Float | BJ30: 0 | BN30: Spare | BO30: Float | BQ30: 0 | BX30: Spare | BY30: Float | CA30: 0 | CE30: Spare | CF30: Float | CH30: 0 | CM30: HVAC SD: Degraded (Text 35, Bit 6) | DK30: =DK29+1 | DL30: Air Horn Low Button(Ahlb) | DN30: 0/1 | DO30: GUI
A31: 21 | B31: ='LFD New'!D34 | C31: Emergency Vent | D31: Boolean | F31: 0 | H31: 39 | K31: Float | U31: Spare | V31: Float | X31: 0 | Z31: 22 | AC31: Float | AJ31: Spare | AK31: Float | AM31: 0 | AO31: 22 | AP31: HVAC1_LIQUID_LINE_SOLENOID_VALVE_1 | AQ31: Liquid Line Solenoid Valve_2 | AR31: Boolean | AT31: 1 | BG31: Spare | BH31: Float | BJ31: 0 | BN31: Spare | BO31: Float | BQ31: 0 | BX31: Spare | BY31: Float | CA31: 0 | CE31: Spare | CF31: Float | CH31: 0 | CM31: RAT/SPT Gap (triggers Hot/Cold Car Fault if > 6K) | DK31: =DK30+1 | DL31: HVAC Reset(SRRB) | DN31: 0/1 | DO31: GUI
A32: 22 | B32: HVAC1_ES | C32: Emergency Stop | D32: Boolean | F32: 0 | H32: 40 | K32: Float | U32: Spare | V32: Float | X32: 0 | Z32: 23 | AC32: Float | AJ32: Spare | AK32: Float | AM32: 0 | AO32: 23 | AP32: HVAC1_SIGHT_GLASS_1 | AQ32: Sight Glass_2 | AR32: Boolean | AT32: 1 | BG32: Spare | BH32: Float | BJ32: 0 | BN32: Spare | BO32: Float | BQ32: 0 | BX32: Spare | BY32: Float | CA32: 0 | CE32: Spare | CF32: Float | CH32: 0 | CM32: Failure Solution / Diagnostic Status | DK32: =DK31+1 | DL32: Emergency Brake Button (Ebb1) | DN32: 0/1 | DO32: GUI
A33: 23 | B33: HVAC1_RATL | C33: Return Air temperature Loop | D33: Float | F33: 23 | H33: 41 | K33: Float | U33: Spare | V33: Float | X33: 0 | Z33: 24 | AC33: Float | AJ33: Spare | AK33: Float | AM33: 0 | AO33: 24 | AP33: HVAC1_TXV_1 | AQ33: Thermal Expansion Valve_2 | AR33: Boolean | AT33: 1 | BG33: Spare | BH33: Float | BJ33: 0 | BN33: Spare | BO33: Float | BQ33: 0 | BX33: Spare | BY33: Float | CA33: 0 | CE33: Spare | CF33: Float | CH33: 0 | CM33: PPR1 / PPR2 (Phase Protection Relay) Status | DK33: =DK32+1 | DL33: Left Door Close Button (Ldcb2) | DN33: 0/1 | DO33: GUI
A34: 24 | B34: HVAC1_CT | C34: Compressor Timer | D34: Integer | F34: 60 | H34: 42 | K34: Integer | U34: Spare | V34: Integer | X34: 0 | Z34: 25 | AC34: Integer | AD34: HVAC IOS _DI | AJ34: Spare | AK34: Integer | AM34: 0 | AO34: 25 | AP34: HVAC1_ELECTRIC_HEATER_2 | AQ34: Electric Heater_2 | AR34: Boolean | AT34: 1 | BG34: Spare | BH34: Integer | BJ34: 0 | BN34: Spare | BO34: Integer | BQ34: 0 | BX34: Spare | BY34: Integer | CA34: 0 | CE34: Spare | CF34: Integer | CH34: 0 | CM34: HVAC Reset Request (1-second signal) | DK34: =DK33+1 | DL34: Left Door Close Button (Ldcb3) | DN34: 0/1 | DO34: GUI
A35: 25 | B35: High Pressure Value | C35: High Pressure Value | D35: ='LFD New'!D2 | F35: 0 | H35: 43 | K35: Integer | U35: Spare | V35: Integer | X35: 0 | Z35: 26 | AC35: Integer | AJ35: Spare | AK35: Integer | AM35: 0 | AQ35: Spare | AR35: Boolean | AT35: 1 | BG35: Spare | BH35: Integer | BJ35: 0 | BN35: Spare | BO35: Integer | BQ35: 0 | BX35: Spare | BY35: Integer | CA35: 0 | CE35: Spare | CF35: Integer | CH35: 0 | CM35: HVAC Mode (OFF, VENT, AUTO) | DK35: =DK34+1 | DL35: Left Door Enable (Pbdel) | DN35: 0/1 | DO35: GUI
A36: 26 | B36: Low pressure Value | C36: Low pressure Value | D36: Integer | F36: 0 | H36: 44 | K36: Integer | U36: Spare | V36: Integer | X36: 0 | Z36: 27 | AC36: Integer | AJ36: Spare | AK36: Integer | AM36: 0 | AQ36: Spare | AR36: Boolean | AT36: 1 | BG36: Spare | BH36: Integer | BJ36: 0 | BN36: Spare | BO36: Integer | BQ36: 1 | BX36: Spare | BY36: Integer | CA36: 0 | CE36: Spare | CF36: Integer | CH36: 0 | CM36: HVAC SD: Emergency ventilation Mode (Text 35, Bit 1) | DK36: =DK35+1 | DL36: Left Door Open Button (Ldob2) | DN36: 0/1 | DO36: GUI
A37: 27 | B37: =ISODD(Calculation!B36) | C37: Set point Temperature | D37: Integer | F37: 23 | H37: 45 | K37: Integer | U37: Spare | V37: Integer | X37: 0 | Z37: 28 | AC37: Integer | AJ37: Spare | AK37: Integer | AM37: 0 | AQ37: Spare | AR37: Boolean | AT37: 1 | BG37: Spare | BH37: Integer | BJ37: 0 | BN37: Spare | BO37: Integer | BQ37: 0 | BX37: Spare | BY37: Integer | CA37: 0 | CE37: Spare | CF37: Integer | CH37: 0 | CM37: Forced Driver FAD Open Status | CP37: 1 | DK37: =DK36+1 | DL37: VCB close (VCBCB) | DN37: 0/1 | DO37: GUI
A38: 28 | B38: RAT | C38: Return Air temperature Loop | D38: Integer | F38: 28 | H38: 46 | K38: Integer | U38: Spare | V38: Integer | X38: 0 | Z38: 29 | AC38: Integer | AJ38: Spare | AK38: Integer | AM38: 0 | AQ38: Spare | AR38: Boolean | BG38: Spare | BH38: Integer | BJ38: 0 | BN38: Spare | BO38: Integer | BQ38: 0 | BX38: Spare | BY38: Integer | CA38: 0 | CE38: Spare | CF38: Integer | CH38: 0 | CM38: Forced Driver FAD Close Status | DK38: =DK37+1 | DL38: VCB Open (VCBOB) | DN38: 0/1 | DO38: GUI
A39: 29 | B39: AT | C39: Ambient Temperature | D39: Integer | F39: 25 | H39: 47 | K39: Integer | U39: Spare | V39: Integer | X39: 0 | Z39: 30 | AC39: Integer | AJ39: Spare | AK39: Integer | AM39: 0 | AQ39: Spare | AR39: Boolean | BG39: Spare | BH39: Integer | BJ39: 0 | BN39: Spare | BO39: Integer | BQ39: 0 | BX39: Spare | BY39: Integer | CA39: 0 | CE39: Spare | CF39: Integer | CH39: 0 | DK39: =DK38+1 | DL39: VCB Reset (VCBRB) | DN39: 0/1 | DO39: GUI
A40: 30 | B40: PL | C40: Passenget Load | D40: Integer | F40: 6 | H40: 48 | K40: Integer | U40: Spare | V40: Integer | X40: 0 | Z40: 31 | AC40: Integer | AE40: =HVAC_IOs!K2 | AJ40: Spare | AK40: Integer | AM40: 0 | AQ40: Spare | AR40: Boolean | BG40: Spare | BH40: Integer | BJ40: 0 | BN40: Spare | BO40: Integer | BQ40: 0 | BX40: Spare | BY40: Integer | CA40: 0 | CE40: Spare | CF40: Integer | CH40: 0 | DK40: =DK39+1 | DL40: Battery close (BATCB) | DN40: 0/1 | DO40: GUI
A41: 31 | B41: ST | C41: Start Time | D41: Integer | F41: 7 | H41: 49 | K41: Integer | U41: Spare | V41: Integer | X41: 0 | Z41: 32 | AC41: Integer | AE41: =HVAC_IOs!K3 | AJ41: Spare | AK41: Integer | AM41: 0 | AQ41: Spare | AR41: Boolean | BG41: Spare | BH41: Integer | BJ41: 0 | BN41: Spare | BO41: Integer | BQ41: 0 | BX41: Spare | BY41: Integer | CA41: 0 | CE41: Spare | CF41: Integer | CH41: 0 | DK41: =DK40+1 | DL41: Battery Open (BATOB) | DN41: 0/1 | DO41: GUI
A42: 32 | B42: CT | C42: Current Time | D42: Integer | F42: 0 | H42: 50 | K42: Integer | U42: Spare | V42: Integer | X42: 0 | Z42: 33 | AC42: Integer | AE42: =HVAC_IOs!K4 | AJ42: Spare | AK42: Integer | AM42: 0 | AQ42: Spare | AR42: Boolean | BG42: Spare | BH42: Integer | BJ42: 0 | BN42: Spare | BO42: Integer | BQ42: 0 | BX42: Spare | BY42: Integer | CA42: 0 | CE42: Spare | CF42: Integer | CH42: 0 | DK42: =DK41+1 | DL42: Pantograph Down (PDB) | DN42: 0/1 | DO42: GUI
A43: 33 | B43: RH | C43: Relative Humidity | D43: Integer | F43: 5 | H43: 51 | K43: Integer | U43: Spare | V43: Integer | X43: 0 | Z43: 34 | AC43: Integer | AE43: =HVAC_IOs!K5 | AJ43: Spare | AK43: Integer | AM43: 0 | AQ43: Spare | AR43: Boolean | BG43: Spare | BH43: Integer | BJ43: 0 | BN43: Spare | BO43: Integer | BQ43: 0 | BX43: Spare | BY43: Integer | CA43: 0 | CE43: Spare | CF43: Integer | CH43: 0 | DK43: =DK42+1 | DL43: Pantograph Up (PUB) | DN43: 0/1 | DO43: GUI
...

Sheet Sheet2

Sheet Calculation
A1: Inputs | I1: Sr. No | J1: Item | K1: Heat Load (W) | L1: Qty | M1: Total Heat Load (W)
A2: c | B2: 1 | C2: KJ/Kg | E2: Outputs | I2: 1 | J2: Passenger | K2: 72.84 | L2: 340 | M2: =K2*L2
A3: Set Point | B3: ='LFD OLD'!F5+273 | C3: K | E3: Return Air | F3: =B18-J32 | G3: C | I3: 2 | J3: Solar Gain | K3: 2336 | L3: 1 | M3: =K3*L3
A4: Ambient Temp | B4: ='LFD OLD'!F7+273 | C4: K | I4: 3 | J4: Transmission Gain | K4: 2882 | L4: 1 | M4: =K4*L4
A5: Supply Temp | B5: ='LFD OLD'!F8+273 | C5: K | I5: 4 | J5: Internal Equipment | K5: 2500 | L5: 1 | M5: =K5*L5
A6: Time | B6: 0.8 | C6: s | E6: Supply Air Temp | F6: =IF(B14=1,(F3+B3-273)/2,F3) | I6: 5 | J6: Fan Motor Load | K6: 4000 | L6: 1 | M6: =K6*L6
A7: Loading | B7: ='DATA TRANSFER'!F40 | C7: pax | I7: 6 | J7: Fresh Air Load | K7: 6663 | L7: 1 | M7: =K7*L7
A8: Heat Load Damper | B8: 0.8 | C8: 0-1 | E8: Damper Pos | F8: =B7*25+25*IF('DATA TRANSFER'!CP18=1,0,1)*IF('DATA TRANSFER'!AE22=0,0,1) | I8: 7 | J8: Door Opening Load | K8: 525 | L8: 1 | M8: =K8*L8
A9: Comp 1 | B9: ='Mode Logic'!L18 | C9: On/off | F9: =IF('DATA TRANSFER'!AE24=1,100,Calculation!F8) | L9: Total Heat Load | M9: =SUM(M2:M8) | N9: W
A10: Comp 2 | B10: ='Mode Logic'!M18 | C10: On/off | D10: HVAC 1 DMA
A11: Comp 3 | B11: ='Mode Logic'!N18 | C11: On/off
A12: Comp 4 | B12: ='Mode Logic'!O18 | C12: On/off | I12: Fresh Air Load
A13: Heater | B13: ='DATA TRANSFER'!M24 | C13: On/off | I13: Air Flow | J13: =IF(B17=1,3037,0)/3600 | K13: m^3/s
A14: FAD | B14: ='DATA TRANSFER'!M16 | I14: Delta T | J14: =B9-B7 | K14: K
A15: Cooling | B15: =IF(AND(B9:B12),47,IF(OR(B9:B12),10,IF(B13=1,-9,0))) | C15: KW
B16: =B15*1000 | C16: W | I16: Heat Load | J16: =J13*J14 | K16: KW
J17: =J16*1000 | K17: W
A18: Internal Temp(RAT) | B18: ='DATA TRANSFER'!F38 | C18: C | L18: ='Mode Logic'!M18
A19: Time Elapsed since Preconditioning | B19: ='DATA TRANSFER'!F34 | C19: mins | D19: Need to add timer start once preconditioning is triggered | I19: Total Heat Load
I20: 1 | J20: Heat Load | K20: =M9 | L20: W
I21: 2 | J21: Freah Air | K21: =J17*G8/100 | L21: W
I22: 3 | J22: Operational | L22: W
A23: Comp 1 | B23: ='DATA TRANSFER'!M41 | C23: On/off | I23: Total Heat Load | K23: =SUM(K20:K22)
A24: Comp 2 | B24: ='DATA TRANSFER'!M42 | C24: On/off | D24: HVAC 1 DMB
A25: Comp 3 | B25: ='DATA TRANSFER'!M43 | C25: On/off
A26: Comp 4 | B26: ='DATA TRANSFER'!M46 | C26: On/off | I26: Change in Temp
A27: Heater | B27: 1 | C27: On/off | I27: 1 | J27: Delta W | K27: =B16-K23 | L27: W
A28: FAD | B28: 1 | I28: 2 | J28: Time | K28: =B6 | L28: s | N28: DM1 HVAC1
A29: Cooling | B29: =IF(AND(B23:B26),47,IF(OR(B23:B26),10,IF(B27=1,-9,0))) | C29: KW | I29: 3 | J29: c | K29: 1 | L29: Kj/Kg.K
B30: =B29*1000 | C30: W | I30: 4 | J30: m | K30: 1000 | L30: Kg
B32: DMA | C32: TCA | D32: DMB | I32: Change | J32: =(1/1000)*(K27*K28)/(K29*K30) | K32: C
A33: Set Point | B33: =IF(TCMS!D24>0,Calculation!O40+TCMS!D24,O40) | C33: =IF(TCMS!E24>0,Calculation!P40+TCMS!E24,P40) | D33: =IF(TCMS!F24>0,Calculation!Q40+TCMS!F24,Q40)
A34: Ambient Temp | B34: ='DATA TRANSFER'!F39 | C34: =B34 | D34: =C34
A35: RAT | B35: ='DATA TRANSFER'!Q584 | C35: ='DATA TRANSFER'!G38 | D35: ='DATA TRANSFER'!H38 | I35: Change in Temp
A36: New RAT | B36: =B35-B90 | C36: =C35-C90 | D36: =D35-B90 | I36: 1 | J36: Delta W | K36: =B15-K23 | L36: W
I37: 2 | J37: Time | K37: =B15 | L37: s | N37: DM1 HVAC2
A38: Pre-Cool | B38: =IF('Mode Logic'!B27=1,1,0) | C38: =B38 | D38: =C38 | E38: =IF(B48=1,0,IF(OR(B38=1,B39=1,B40=1),0,IF('Mode Logic'!B30=1,1,0)))*IF(B50=1,0,1) | F38: ='DATA TRANSFER'!F38 | I38: 3 | J38: c | K38: 1 | L38: Kj/Kg.K
A39: Pre-heat | B39: =IF('Mode Logic'!B26=1,1,0) | C39: =B39 | D39: =C39 | I39: 4 | J39: m | K39: 1000 | L39: Kg
A40: Auto Cool 1 (Cooling Circuits Disabled) | B40: =IF(B48=1,0,IF(B38=0,IF('Mode Logic'!B29=1,1,0)))*IF(B50=1,0,1) | C40: =B40 | D40: =IF(OR(D48=0,D38=0,D50=0),1,IF(AND(D35>=D33+1.5,D35<D33+2.5),1,0)) | E40: FAT<T4 | G40: =IF(OR(B48=0,B38=0,B50=0),1,IF(AND(B35>=B33+1.5,B35<B33+2.5),1,0))
A41: Auto Cool 2 | B41: =IF(B48=1,0,IF(OR(B38=1,B39=1,B40=1),0,IF('Mode Logic'!B30=1,1,0)))*IF(B50=1,0,1) | C41: =B41 | D41: =IF(OR(D48=1,D38=1,D50=1),0,IF(AND(D35>=D33,D35<D33+1),1,0)) | I41: Change | J41: =(1/1000)*(K36*K37)/(K38*K39) | K41: C
...

Sheet Mode Logic
B1: Inputs | F1: Temp | G1: Values | H1: Kelvin | J1: For Operating Panel Screen
B2: c | C2: 1 | D2: KJ/Kg | F2: T1 | G2: 18 | H2: =G2+273.15 | J2: Status | K2: Modes of Operation | L2: Compressor 1 | M2: Compressor 2 | N2: Compressor 3 | O2: Compressor 4 | P2: FAD | Q2: RAD | R2: Heater | S2: Condensor Fan | T2: Evaporator Fan 1 | U2: Evaporator Fan 2
B3: Set Point | C3: ='DATA TRANSFER'!F37+273.15 | D3: K | F3: T2 | G3: 25 | H3: =G3+273.15 | J3: {=IF(AND(J13:J15=0,J6=0),IF(AND(Calculation!B33>Calculation!B35,C3-C19>3,C7<=10%,C21<=60,C20<60),1,0),0)} | K3: =C26 | L3: =H26 | M3: =I26 | N3: =J26 | O3: =K26 | P3: 0 | Q3: =Calculation!$B$52 | R3: 1 | S3: 0 | T3: 1 | U3: 1 | AB3: Preconditioning: Preheating
B4: Ambient Temp | C4: ='DATA TRANSFER'!F39+273.15 | D4: K | F4: T3 | G4: 43 | H4: =G4+273.15 | J4: {=IF(AND(J13:J15=0),B27,0)} | K4: =C27 | L4: 1 | M4: 1 | N4: 1 | O4: 1 | P4: 0 | Q4: 1 | R4: 0 | S4: 1 | T4: 1 | U4: 1 | AB4: Preconditioning: Precooling
B5: Supply Temp | C5: ='DATA TRANSFER'!F39+273.15 | D5: K | F5: T4 | G5: 10 | H5: =G5+273.15 | J5: =B28 | K5: =C28 | P5: 1 | Q5: 1 | R5: 0 | S5: 1 | T5: 1 | U5: 1 | AB5: Cooling Mode
B6: Time | C6: 0.8 | D6: s | F6: T5 | G6: 11 | H6: =G6+273.15 | J6: =IF(AND('DATA TRANSFER'!Q584-Calculation!B33>=-0.5,'DATA TRANSFER'!Q584-Calculation!B33<0.5,J13=0,J14=0,J15=0),1,0) | K6: =C29 | L6: 0 | M6: 0 | N6: 0 | O6: 0 | P6: 0 | Q6: 0 | R6: 0 | S6: 1 | T6: 1 | U6: 1 | AB6: Standard Automatic Cooling State 1 (Cooling Circuits Disabled)
B7: Loading | C7: =E7/100 | D7: % | E7: ='DATA TRANSFER'!F40 | F7: T6 | G7: 12 | H7: =G7+273.15 | J7: {=IF(AND(B31=1,Calculation!B35-Calculation!B33>=0.5,Calculation!B35-Calculation!B33<3,J13:J15=0),1,0)} | K7: Standard Automatic Cooling State 2 (Up to 25% Modulated Cooling) | L7: 1 | M7: 0 | N7: 0 | O7: 0 | P7: 0 | Q7: 1 | R7: 0 | S7: 1 | T7: 1 | U7: 1 | AB7: Standard Automatic Cooling State 2 (Up to 25% Modulated Cooling)
B8: Current Mode | C8: =IFERROR(VLOOKUP(1,B26:C39,2,FALSE)," ") | D8: 0-1 | F8: T7 | G8: 30 | H8: =G8+273.15 | J8: {=IF(AND(B31=1,Calculation!B35-Calculation!B33>=3,Calculation!B35-Calculation!B33<4.5,J13:J15=0),1,0)} | K8: Standard Automatic Cooling State 3 (Up to 50% Modulated Cooling) | L8: 1 | M8: 1 | N8: 0 | O8: 0 | P8: 0 | Q8: 1 | R8: 0 | S8: 1 | T8: 1 | U8: 1 | AB8: Standard Automatic Cooling State 3 (Up to 50% Modulated Cooling)
B9: Comp 1 | C9: =IFERROR(VLOOKUP($C$8,$C$26:$H$40,6,FALSE)," ") | D9: On/off | F9: RAT | G9: 32 | H9: =G9+273.15 | J9: {=IF(AND(B31=1,Calculation!B35-Calculation!B33>=4.5,Calculation!B35-Calculation!B33<6,J13:J15=0),1,0)} | K9: Standard Automatic Cooling State 4 (Up to 75% Modulated Cooling) | L9: 1 | M9: 1 | N9: 1 | O9: 0 | P9: 0 | Q9: 1 | R9: 0 | S9: 1 | T9: 1 | U9: 1 | AB9: Standard Automatic Cooling State 4 (Up to 75% Modulated Cooling)
B10: Comp 2 | C10: =IFERROR(VLOOKUP($C$8,$C$26:$M$40,7,FALSE)," ") | D10: On/off | F10: FAT | G10: =C18 | H10: =G10+273.15 | J10: {=IF(AND(B31=1,Calculation!B35-Calculation!B33>=6,J13:J15=0),1,0)} | K10: Standard Automatic Cooling State 5 (Up to 100% Modulated Cooling) | L10: 1 | M10: 1 | N10: 1 | O10: 1 | P10: 0 | Q10: 1 | R10: 1 | S10: 1 | T10: 1 | U10: 1 | AB10: Standard Automatic Cooling State 5 (Up to 100% Modulated Cooling) | CD10: ='DATA TRANSFER'!F38
B11: Comp 3 | C11: =IFERROR(VLOOKUP($C$8,$C$26:$M$40,8,FALSE)," ") | D11: On/off | F11: SAT | J11: {=IF(AND(J6=0,J12:J15=0,J3=0),B32,0)} | K11: =C32 | L11: =IF(AND(L13=0,L14=0),H32,0) | M11: =I32 | N11: =J32 | O11: =K32 | P11: 1 | Q11: 1 | R11: 0 | S11: 0 | T11: 1 | U11: 1 | AB11: Ventilation Mode
B12: Comp 4 | C12: =IFERROR(VLOOKUP($C$8,$C$26:$M$40,9,FALSE)," ") | D12: On/off | F12: Set Point | G12: =Calculation!B33 | J12: {=IF(AND(J13:J15=0,J3=0),B33,0)} | K12: =C33 | L12: =H32 | M12: =I33 | N12: =J33 | O12: =K33 | P12: 0 | Q12: 1 | R12: 1 | S12: 0 | T12: 1 | U12: 1 | AB12: Heating Mode
B13: Heater | C13: =IFERROR(VLOOKUP($C$8,$C$26:$M$40,2,FALSE)," ") | D13: On/off | F13: old rat | G13: =Calculation!B35 | J13: ='DATA TRANSFER'!F28 | K13: =C34 | L13: =H33 | M13: 0 | N13: 0 | O13: 0 | P13: 0 | Q13: 0 | R13: 0 | S13: 0 | T13: 0 | U13: 0 | AB13: Internal Smoke Mode
B14: FAD | C14: =IFERROR(VLOOKUP($C$8,$C$26:$M$40,10,FALSE)," ") | F14: new rat | G14: =Calculation!B36 | J14: ='DATA TRANSFER'!F29 | K14: =C35 | L14: 1 | M14: 1 | N14: 1 | O14: 1 | P14: 0 | Q14: 1 | R14: 0 | S14: 1 | T14: 1 | U14: 1 | AB14: External Smoke Mode
B15: RAD | C15: =IFERROR(VLOOKUP($C$8,$C$26:$M$40,11,FALSE)," ") | J15: ='DATA TRANSFER'!F31 | K15: =C37 | L15: 0 | M15: 0 | N15: 0 | O15: 0 | P15: 0 | Q15: 0 | R15: 0 | S15: 0 | T15: 1 | U15: 1 | AB15: Emergency Ventilation Mode
B16: Cooling | D16: KW
C17: =C16*1000 | K17: Current Mode | L17: Compressor 1 | M17: Compressor 2 | N17: Compressor 3 | O17: Compressor 4 | P17: =P2 | Q17: =Q2 | R17: =R2 | S17: =S2 | T17: Condensor Fan 2 | U17: =T2 | V17: =U2
B18: Fresh Air Temp (FAT) | C18: ='DATA TRANSFER'!F39 | D18: oc | J18: =VLOOKUP(1,J3:K15,1,FALSE) | K18: =VLOOKUP(1,J3:P15,2,FALSE) | L18: =VLOOKUP($K$18,$K$3:$O$15,2,FALSE) | M18: =VLOOKUP($K$18,$K$3:$O$15,3,FALSE) | N18: =VLOOKUP($K$18,$K$3:$O$15,4,FALSE) | O18: =VLOOKUP($K$18,$K$3:$O$15,5,FALSE) | P18: =VLOOKUP($K$18,$K$3:$U$15,6,FALSE) | Q18: =VLOOKUP($K$18,$K$3:$U$15,7,FALSE) | R18: =VLOOKUP($K$18,$K$3:$U$15,8,FALSE) | S18: =VLOOKUP($K$18,$K$3:$U$15,9,FALSE) | T18: =S18 | U18: =VLOOKUP($K$18,$K$3:$U$15,10,FALSE) | V18: =VLOOKUP($K$18,$K$3:$U$15,11,FALSE)
B19: =Calculation!B36+273.15 | C19: =Calculation!B35+273.15 | D19: K | S19: =VLOOKUP($K$18,$K$3:$U$15,9,FALSE)
B20: Time Since HVAC ON | C20: =Calculation!B19 | D20: min
B21: Relative Humiditty | C21: ='DATA TRANSFER'!F43
A25: Sr No | B25: Status of Operation | C25: Status | D25: Heater | E25: Condensor Fan | F25: Evaporator Fan 1 | G25: Evaporator Fan 2 | H25: Compressor 1 | I25: Compressor 2 | J25: Compressor 3 | K25: Compressor 4 | L25: FAD | M25: RAD | N25: Remarks
A26: 1 | B26: 0 | C26: Preconditioning: Preheating | D26: 1 | E26: 0 | F26: 1 | G26: 1 | H26: 0 | I26: 0 | J26: 0 | K26: 0 | L26: 0 | M26: =Calculation!$B$52 | N26: pre-Heating operation
A27: 2 | B27: =IF(AND(C19-C3>3,C7<=10%,C21<=60,Calculation!B19<60,B32=0),1,0) | C27: Preconditioning: Precooling | D27: 0 | E27: 1 | F27: 1 | G27: 1 | H27: 1 | I27: 1 | J27: 1 | K27: 1 | L27: 0 | M27: 1 | N27: pre-Cooling operation
A28: 3 | B28: 0 | C28: Cooling Mode | D28: 0 | E28: 1 | F28: 1 | G28: 1 | H28: 1 | I28: 1 | J28: 1 | K28: 1 | L28: 1 | M28: 1 | N28: Cooling demand dependent
A29: 4 | B29: {=IF(AND(B26:B27=0,B32=0),IF(C18<G5,1,0),0)} | C29: Standard Automatic Cooling State 1 (Cooling Circuits Disabled) | D29: 0 | E29: 0 | F29: 1 | G29: 1 | H29: 0 | I29: 0 | J29: 0 | K29: 0 | L29: 0 | M29: 0
A30: 5 | B30: =IF(AND(H5<=H10,H10<H7,B32=0),1,0) | C30: Standard Automatic Cooling State 2 (Up to 50% Modulated Cooling) | D30: =IF(J15=0,IF(AND(Calculation!B33>Calculation!B35,C3-C19>3,C7<=10%,C21<=60,C20<=60),1,0)) | E30: 1 | F30: 1 | G30: 1 | H30: 1 | I30: 1 | J30: 0 | K30: 0
A31: 6 | B31: {=IF(AND(B26:B27=0,B32=0,B34=0,B35=0),IF(C18>=G7,1,0),0)} | C31: Standard Automatic Cooling State 3 (Up to 100% Modulated Cooling) | D31: 0 | E31: 1 | F31: 1 | G31: 1 | H31: 1 | I31: 1 | J31: 1 | K31: 1
A32: 7 | B32: =IF(AND(B26=0),Calculation!B67,0) | C32: Ventilation Mode | D32: 0 | E32: 0 | F32: 1 | G32: 1 | H32: 0 | I32: 0 | J32: 0 | K32: 0 | L32: 0 | M32: 1 | N32: Fresh air intake closed
A33: 8 | B33: =IF(Calculation!B33-Calculation!B35>5,1,0) | C33: Heating Mode | D33: 1 | E33: 0 | F33: 1 | G33: 1 | H33: 0 | I33: 0 | J33: 0 | K33: 0 | L33: 0/1 | M33: 1 | N33: Cooling/dehumidification with possible reheat
A34: 9 | B34: 0 | C34: Internal Smoke Mode | D34: 0 | E34: 0 | F34: 1 | G34: 1 | H34: 0 | I34: 0 | J34: 0 | K34: 0 | L34: 1 | M34: 0 | N34: Maximum ventilation / smoke removal
A35: 10 | B35: 0 | C35: External Smoke Mode | D35: 0 | E35: 0 | F35: 1 | G35: 1 | H35: 0 | L35: 0 | M35: 1
A36: 11 | C36: Dehumidification Mode | D36: 0/1 | E36: 1 | F36: 1 | G36: 1 | H36: 1 | L36: 0 | M36: 1
A37: 12 | C37: Emergency Ventilation Mode | D37: 0 | E37: 0/1 | F37: 1 | G37: 1 | H37: 0 | L37: 1 | M37: 1
A38: 13 | F38: ='DATA TRANSFER'!F38
A39: 14 | G39: ='DATA TRANSFER'!G38
A40: 15 | E40: =IF(OR(E26:E36),1,0)
B42: HVAC Staggered Start
B43: Compressor 1 | C43: =IF('DATA TRANSFER'!CP23=1,1,0)
B44: Time Elapsed since Compressor 1 start | C44: ='DATA TRANSFER'!Q587
...

Sheet HVAC MODES IN NORMAL OPERATION
A1: MODE | B1: Passenger Load | C1: Season | D1: Time | E1: Ambient Temp Min | F1: Ambient Temp Max | G1: Set Point Min | H1: Set Point Max | I1: RH Min | J1: RH Max | K1: Return Air Temperature
A2: Fresh Air Ventilation | B2: AW0 | C2: Summer, Rainy, Winter | D2: Morning, Afternoon, Night | E2: 15 | F2: 50 | G2: 18 | H2: 34 | I2: 0.4 | J2: 0.6 | K2: Initial = Ambient, Final = Set Point
A3: COOL 1 | B3: AW0 Laod 0, AW1 Load 50 ,AW2 Load 300, AW3 Load 380 | C3: Summer | D3: Morning | E3: 25 | F3: 36 | G3: 18 | H3: 34 | I3: 0.4 | J3: 0.6 | K3: RAT > Set Point
D4: Afternoon | E4: 36 | F4: 42.5 | G4: 18 | H4: 34 | I4: 0.4 | J4: 0.6 | K4: RAT > Set Point
D5: Night | E5: 25 | F5: 32 | G5: 18 | H5: 34 | I5: 0.4 | J5: 0.6 | K5: RAT > Set Point
C6: Rainy | D6: Morning | E6: 25 | F6: 30 | G6: 18 | H6: 34 | I6: 0.5 | J6: 0.75 | K6: RAT > Set Point
D7: Afternoon | E7: 30 | F7: 33 | G7: 18 | H7: 34 | I7: 0.5 | J7: 0.75 | K7: RAT > Set Point
D8: Night | E8: 25 | F8: 28 | G8: 18 | H8: 34 | I8: 0.5 | J8: 0.75 | K8: RAT > Set Point
C9: Winter | D9: Morning | E9: 4 | F9: 18 | G9: 18 | H9: 34 | I9: 0.3 | J9: 0.6 | K9: RAT > Set Point
D10: Afternoon | E10: 18 | F10: 28 | G10: 18 | H10: 34 | I10: 0.3 | J10: 0.6 | K10: RAT > Set Point
D11: Night | E11: 4 | F11: 15 | G11: 18 | H11: 34 | I11: 0.3 | J11: 0.6 | K11: RAT > Set Point
A12: COOL 2 | B12: AW0 Laod 0, AW1 Load 50 ,AW2 Load 300, AW3 Load 380 | C12: Summer | D12: Morning | E12: 25 | F12: 36 | G12: 18 | H12: 34 | I12: 0.4 | J12: 0.6 | K12: RAT > SP
D13: Afternoon | E13: 36 | F13: 50 | G13: 18 | H13: 34 | I13: 0.4 | J13: 0.6 | K13: RAT > SP
D14: Night | E14: 25 | F14: 32 | G14: 18 | H14: 34 | I14: 0.4 | J14: 0.6 | K14: RAT > SP
C15: Rainy | D15: Morning | E15: 25 | F15: 30 | G15: 18 | H15: 34 | I15: 0.5 | J15: 0.75 | K15: RAT > SP
D16: Afternoon | E16: 30 | F16: 33 | G16: 18 | H16: 34 | I16: 0.5 | J16: 0.75 | K16: RAT > SP
D17: Night | E17: 25 | F17: 28 | G17: 18 | H17: 34 | I17: 0.5 | J17: 0.75 | K17: RAT > SP
C18: Winter | D18: Morning | E18: 4 | F18: 18 | G18: 18 | H18: 34 | I18: 0.3 | J18: 0.6 | K18: RAT > SP
D19: Afternoon | E19: 18 | F19: 28 | G19: 18 | H19: 34 | I19: 0.3 | J19: 0.6 | K19: RAT > SP
D20: Night | E20: 4 | F20: 15 | G20: 18 | H20: 34 | I20: 0.3 | J20: 0.6 | K20: RAT > SP
A21: Dehumidification | B21: AW0 Laod 0, AW1 Load 50 ,AW2 Load 300, AW3 Load 380 | C21: Summer, Rainy | D21: Morning, Afternoon, Night | E21: 25 | F21: 33 | G21: 18 | H21: 34 | I21: 0.6 | J21: 0.85 | K21: RAT ≈ SP
A22: Pre-Cooling | B22: AW0 Laod 0, AW1 Load 50 ,AW2 Load 300, AW3 Load 380 | C22: Summer | D22: Morning | E22: 30 | F22: 42.5 | G22: 18 | H22: 34 | I22: 0.4 | J22: 0.6 | K22: Initial = Ambient, Final = Set Point
D23: Afternoon | E23: 36 | F23: 50 | G23: 18 | H23: 34 | I23: 0.4 | J23: 0.6 | K23: Initial = Ambient, Final = Set Point
D24: Night | E24: 30 | F24: 36 | G24: 18 | H24: 34 | I24: 0.4 | J24: 0.6 | K24: Initial = Ambient, Final = Set Point
A25: Pre-Heating | B25: AW0 Laod 0, AW1 Load 50 ,AW2 Load 300, AW3 Load 380 | C25: Winter | D25: Morning | E25: 4 | F25: 15 | G25: 18 | H25: 34 | I25: 0.3 | J25: 0.6 | K25: Initial = Ambient Temp, Final = Set Point
D26: Afternoon | E26: 15 | F26: 20 | G26: 18 | H26: 34 | I26: 0.3 | J26: 0.6 | K26: Initial = Ambient Temp, Final = Set Point
D27: Night | E27: 4 | F27: 15 | G27: 18 | H27: 34 | I27: 0.3 | J27: 0.6 | K27: Initial = Ambient Temp, Final = Set Point
A28: Emergency Ventilation | B28: AW0 Laod 0, AW1 Load 50 ,AW2 Load 300, AW3 Load 380 | C28: Summer, Rainy, Winter | D28: Any | E28: Any | F28: Any | G28: — | H28: — | I28: — | J28: — | K28: Temperature independent
A29: Ambient Smoke Mode | B29: AW0 Laod 0, AW1 Load 50 ,AW2 Load 300, AW3 Load 380 | C29: Any | D29: Any | E29: Any | F29: Any | G29: — | H29: — | I29: — | J29: — | K29: Temperature independent
A30: Internal Smoke Mode | B30: AW0 Laod 0, AW1 Load 50 ,AW2 Load 300, AW3 Load 380 | C30: Any | D30: Any | E30: Any | F30: Any | G30: — | H30: — | I30: — | J30: — | K30: Temperature independent

Sheet LFD OLD
A1: Sr. No | B1: Component ID | C1: Component Name | D1: Description | E1: Comment | F1: Labview input | G1: Logical Condition | R1: Status | AE1: COOLING STATUS ATTRIBUTES SUMMARY | BL1: LFD INPUTS TO EXCEL
G2: Dependency 1 LabView Input | H2: Dependency 2 | I2: Dependency 3 | J2: Dependency 4 | K2: Dependency 5 | L2: Dependency 6 | M2: Dependency 7 | N2: Dependency 8 | O2: Dependency 9 | P2: Dependency 10 | Q2: Dependency 11
A4: Additional Inputs | AF4: Mode | AG4: Cool 2 | AH4: Cool 1 | AI4: Preheat | AJ4: PreCool | AK4: Vent | AL4: Heat | AM4: Humidity | AN4: Emergency | AP4: Priority | AQ4: Preheat | AR4: PreCool | AS4: Cool2 | AT4: Cool1 | AU4: Vent | AV4: Humidity | AW4: Heat | AX4: Emergency
A5: 1 | B5: Set Point | E5: TCMS | F5: =Calculation!B33 | G5: Cool 2 | H5: Cool 1 | I5: Vent | J5: Heat | K5: Humidity | L5: Emergency Vent Mode | M5: External Smoke mode | N5: Internal smoke mode | W5: ='DATA TRANSFER'!F43 | AF5: Status | AG5: =R103 | AH5: =R103 | AI5: =R273 | AJ5: =R292 | AK5: =R42 | AL5: =R150
A6: 2 | B6: HAVC1_RATSI_1 | D6: Return Air Temp | E6: I/O | F6: =Calculation!B35 | G6: =IF(OR(V9=1,M6=0,V16=1,Calculation!D107=0,Calculation!D104=0,Calculation!D107=0),1,0) | H6: =IF(AND(Calculation!B67=1,'LFD OLD'!G11=0,'LFD OLD'!H11=0,'LFD OLD'!K6=0,'LFD OLD'!V17=1,'LFD OLD'!V9=1,Calculation!D107=0,Calculation!D104=0),1,0) | J6: =IF(F6 < (F5 - 0.5), 1, 0) | K6: =IF(F9>60,1,0) | L6: ='DATA TRANSFER'!CP36 | M6: ='DATA TRANSFER'!AE22 | N6: ='DATA TRANSFER'!AE21 | U6: passenger load | V6: ='DATA TRANSFER'!F40 | AF6: Fault | AH6: =IF(AND(R106:R109),1,0) | AI6: =IF(AND(R276:R279,R281),1,0) | AJ6: =IF(AND(R294:R298,R299),1,0)
A7: 3 | B7: HVAC1_FATSI_1 | D7: Ambient Temp | E7: I/O | F7: =Calculation!B34 | G7: cooling level 1 to 8 | H7: level 1 | I7: level 2 | J7: level 3 | K7: level 4 | L7: level 5 | M7: level 6 | N7: level 7 | O7: level 8 | U7: Pre-cool | V7: =IF(($W$5>=40)*($W$5<=60),1,0)
A8: 4 | B8: HVAC1_SATSI_1 | D8: Supply Air Temp | E8: I/O | F8: ='Mode Logic'!C18 | H8: =IF(OR(Calculation!B67=1,V9=1,M6=0,V16=1),1,0) | I8: =IF(OR(Calculation!B67=1,V9=1,M6=0,V17=1,G11=0,H11=0,K6=0,Calculation!D107=0,Calculation!D104=0,Calculation!D107=0),1,0) | J8: =IF(OR(Calculation!B67=1,V9=1,M6=0,V18=1,G11=0,H11=0,K6=0,Calculation!D107=0,Calculation!D104=0,Calculation!D107=0),1,0) | K8: =IF(OR(Calculation!B67=1,V9=1,M6=0,V19=1,G11=0,H11=0,K6=0,Calculation!D107=0,Calculation!D104=0,Calculation!D107=0),1,0) | L8: =IF(OR(Calculation!B67=1,V9=1,M6=0,V20=1,G11=0,H11=0,K6=0,Calculation!D107=0,Calculation!D104=0,Calculation!D107=0),1,0) | M8: =IF(OR(Calculation!B67=1,V9=1,M6=0,V21=1,G11=0,H11=0,K6=0,Calculation!D107=0,Calculation!D104=0,Calculation!D107=0),1,0) | N8: =IF(OR(Calculation!B67=1,V9=1,M6=0,V22=1,G11=0,H11=0,K6=0,Calculation!D107=0,Calculation!D104=0,Calculation!D107=0),1,0) | O8: =IF(OR(Calculation!B67=1,V9=1,M6=0,V23=1,G11=0,H11=0,K6=0,Calculation!D107=0,Calculation!D104=0,Calculation!D107=0),1,0) | U8: Pre-heat | V8: =IF(($W$5>=4)*($W$5<=18), 1, 0) | AE8: Commands from Cooling Status Attributes
A9: 5 | B9: HVAC1_RHTSI_1 | D9: Relative Humidity | E9: I/O | F9: ='Mode Logic'!C21 | U9: Cooling level 1 to 8, vent | V9: =IF(($W$5>=50)*AND($W$5<=60),1,0) | AG9: PreCool | AH9: Preheat | AI9: Cool2 | AJ9: Cool1 | AK9: Vent | AL9: Humidity | AM9: Heat | AN9: Emergency | AO9: PreCool | AP9: Preheat | AQ9: Cool2 | AR9: Cool1 | AS9: Vent | AT9: Humidity | AU9: Heat | AV9: Emergency | AW9: Command | AZ9: Emergency Vent Mode | BA9: Internal Smoke mode | BB9: External smoke mode | BD9: Emergency Vent Mode | BE9: Internal Smoke mode | BF9: External smoke mode
A10: 6 | D10: Passenger Loading | E10: I/O | F10: ='DATA TRANSFER'!F40 | G10: PCOOL | H10: PHEAT | U10: Dehumidification | V10: =IF(W5>60,1,0) | AE10: 1 | AF10: HAVC1_COMP_1 | AG10: =R303 | AH10: =R284 | AI10: =Q112 | AJ10: =R112 | AO10: =AG10 | AP10: =AH10 | AQ10: =IF(AG10=1,1,AI10) | AR10: =IF(OR(AG10,AI10),1,AJ10) | AS10: =IF(OR(AG10:AJ10),1,AK10) | AT10: =IF(OR(AG10:AK10),1,AL10) | AU10: =IF(OR(AG10:AL10),1,AM10) | AV10: =IF(OR(AG10:AM10),1,AN10) | AW10: =AV10 | AY10: HAVC1_COMP_1 | AZ10: ='CIRCUIT SIM'!L696 | BA10: ='CIRCUIT SIM'!Q696 | BB10: ='CIRCUIT SIM'!S696 | BD10: =IF(OR(AG10:AN10,BA10,BB10),1,AZ10) | BE10: =IF(OR(AG10:AN10,AZ10,BB10),1,BA10) | BF10: =IF(OR(AG10:AN10,AZ10:BA10),1,BB10)
A11: 7 | B11: Chk_TDR Precool | D11: HVAC1_START Time | E11: I/O | F11: =HVAC_IOs!D51-HVAC_IOs!D50 | G11: =Calculation!B40 | H11: =Calculation!B39 | AE11: 2 | AF11: HAVC1_COMP_2 | AG11: =R304 | AH11: =R285 | AI11: =Q113 | AJ11: =R113 | AO11: =AG11 | AP11: =IF(AG11,1,AH11) | AQ11: =IF(OR(AG11:AH11),1,AI11) | AR11: =IF(OR(AG11:AI11),1,AJ11) | AS11: =IF(OR(AG11:AJ11),1,AK11) | AT11: =IF(OR(AG11:AK11),1,AL11) | AU11: =IF(OR(AG11:AL11),1,AM11) | AV11: =IF(OR(AG11:AM11),1,AN11) | AW11: =AV11 | AY11: HAVC1_COMP_2 | AZ11: ='CIRCUIT SIM'!L697 | BA11: ='CIRCUIT SIM'!Q697 | BB11: ='CIRCUIT SIM'!S697 | BD11: =IF(OR(AG11:AN11,BA11,BB11),1,AZ11) | BE11: =IF(OR(AG11:AN11,AZ11,BB11),1,BA11) | BF11: =IF(OR(AG11:AN11,AZ11:BA11),1,BB11)
A12: 8 | B12: Pumpdown_CHk | D12: Pumodown (Managed Shutdown) Check | F12: =HVAC_IOs!D52 | U12: Vent temperature | V12: =IF(F6<=F5-0.5,1,0) | AE12: 3 | AF12: HAVC1_COMP_3 | AG12: =R305 | AH12: =R286 | AI12: =Q114 | AJ12: =R114 | AO12: =AG12 | AP12: =IF(AG12,1,AH12) | AQ12: =IF(OR(AG12:AH12),1,AI12) | AR12: =IF(OR(AG12:AI12),1,AJ12) | AS12: =IF(OR(AG12:AJ12),1,AK12) | AT12: =IF(OR(AG12:AK12),1,AL12) | AU12: =IF(OR(AG12:AL12),1,AM12) | AV12: =IF(OR(AG12:AM12),1,AN12) | AY12: HAVC1_COMP_3 | AZ12: ='CIRCUIT SIM'!L698 | BA12: ='CIRCUIT SIM'!Q698 | BB12: ='CIRCUIT SIM'!S698 | BD12: =IF(OR(AG12:AN12,BA12,BB12),1,AZ12) | BE12: =IF(OR(AG12:AN12,AZ12,BB12),1,BA12) | BF12: =IF(OR(AG12:AN12,AZ12:BA12),1,BB12)
A13: 9 | B13: Equilization_Chk | D13: Equilization Runtime check | F13: =HVAC_IOs!D53 | J13: Aux Supply | L13: isolate | M13: =TCMS!C105 | AE13: 4 | AF13: HAVC1_COMP_4 | AG13: =R306 | AH13: =R287 | AI13: =Q115 | AJ13: =R115 | AO13: =AG13 | AP13: =IF(AG13,1,AH13) | AQ13: =IF(OR(AG13:AH13),1,AI13) | AR13: =IF(OR(AG13:AI13),1,AJ13) | AS13: =IF(OR(AG13:AJ13),1,AK13) | AT13: =IF(OR(AG13:AK13),1,AL13) | AU13: =IF(OR(AG13:AL13),1,AM13) | AV13: =IF(OR(AG13:AM13),1,AN13) | AY13: HAVC1_COMP_4 | AZ13: ='CIRCUIT SIM'!L699 | BA13: ='CIRCUIT SIM'!Q699 | BB13: ='CIRCUIT SIM'!S699 | BD13: =IF(OR(AG13:AN13,BA13,BB13),1,AZ13) | BE13: =IF(OR(AG13:AN13,AZ13,BB13),1,BA13) | BF13: =IF(OR(AG13:AN13,AZ13:BA13),1,BB13)
A14: 10 | B14: Chk_TDR LP | D14: LP Cutout | F14: 1 | U14: set point | V14: ='DATA TRANSFER'!F37 | AE14: 5 | AF14: HVAC1_CF_1 | AG14: =R307 | AH14: =R288 | AI14: =P114 | AJ14: =Q114 | AO14: =AG14 | AP14: =IF(AG14,1,AH14) | AQ14: =IF(OR(AG14:AH14),1,AI14) | AR14: =IF(OR(AG14:AI14),1,AJ14) | AS14: =IF(OR(AG14:AJ14),1,AK14) | AT14: =IF(OR(AG14:AK14),1,AL14) | AU14: =IF(OR(AG14:AL14),1,AM14) | AV14: =IF(OR(AG14:AM14),1,AN14) | AY14: HVAC1_CF_1 | AZ14: ='CIRCUIT SIM'!L700 | BA14: ='CIRCUIT SIM'!Q700 | BB14: ='CIRCUIT SIM'!S700 | BD14: =IF(OR(AG14:AN14,BA14,BB14),1,AZ14) | BE14: =IF(OR(AG14:AN14,AZ14,BB14),1,BA14) | BF14: =IF(OR(AG14:AN14,AZ14:BA14),1,BB14)
A15: 11 | B15: Chk_TDR Comp1 | D15: TDR Comp1 | F15: =HVAC_IOs!D47 | U15: cooling level | V15: ='DATA TRANSFER'!F38 | AE15: 6 | AF15: HVAC1_CF_2 | AG15: =R308 | AH15: =R289 | AI15: =P115 | AJ15: =Q115 | AO15: =AG15 | AP15: =IF(AG15,1,AH15) | AQ15: =IF(OR(AG15:AH15),1,AI15) | AR15: =IF(OR(AG15:AI15),1,AJ15) | AS15: =IF(OR(AG15:AJ15),1,AK15) | AT15: =IF(OR(AG15:AK15),1,AL15) | AU15: =IF(OR(AG15:AL15),1,AM15) | AV15: =IF(OR(AG15:AM15),1,AN15) | AY15: HVAC1_CF_2 | AZ15: ='CIRCUIT SIM'!L701 | BA15: ='CIRCUIT SIM'!Q701 | BB15: ='CIRCUIT SIM'!S701 | BD15: =IF(OR(AG15:AN15,BA15,BB15),1,AZ15) | BE15: =IF(OR(AG15:AN15,AZ15,BB15),1,BA15) | BF15: =IF(OR(AG15:AN15,AZ15:BA15),1,BB15)
A16: 12 | B16: CHk_TDR Comp2 | C16: E1 | D16: TDR Comp 2 | F16: =HVAC_IOs!D54 | U16: level 1 | V16: =IF(AND(V15>=V14+0.5,V15<V14+1.5),1,0) | AE16: 7 | AF16: Command_RAD | AG16: =R309 | AH16: =R290 | AI16: =P111 | AJ16: =Q111 | AM16: =R156 | AO16: =AG16 | AP16: =IF(AG16,1,AH16) | AQ16: =IF(OR(AG16:AH16),1,AI16) | AR16: =IF(OR(AG16:AI16),1,AJ16) | AS16: =IF(OR(AG16:AJ16),1,AK16) | AT16: =IF(OR(AG16:AK16),1,AL16) | AU16: =IF(OR(AG16:AL16),1,AM16) | AV16: =IF(OR(AG16:AM16),1,AN16) | AY16: Command_RAD | AZ16: ='CIRCUIT SIM'!L702 | BA16: ='CIRCUIT SIM'!Q702 | BB16: ='CIRCUIT SIM'!S702 | BD16: =IF(OR(AG16:AN16,BA16,BB16),1,AZ16) | BE16: =IF(OR(AG16:AN16,AZ16,BB16),1,BA16) | BF16: =IF(OR(AG16:AN16,AZ16:BA16),1,BB16)
A17: 13 | D17: Internal Smoke (NOT) | U17: level 2 | V17: =IF(AND(V15>=V14+1.5,V15<V14+2.5),1,0) | AE17: 8 | AF17: Command_FAD_1 | AG17: =R310 | AH17: =R291 | AI17: =R113 | AJ17: =S113 | AM17: =R156 | AO17: =AG17 | AP17: =IF(AG17,1,AH17) | AQ17: =IF(OR(AG17:AH17),1,AI17) | AR17: =IF(OR(AG17:AI17),1,AJ17) | AS17: =IF(OR(AG17:AJ17),1,AK17) | AT17: =IF(OR(AG17:AK17),1,AL17) | AU17: =IF(OR(AG17:AL17),1,AM17) | AV17: =IF(OR(AG17:AM17),1,AN17) | AY17: Command_FAD_1 | AZ17: ='CIRCUIT SIM'!L703 | BA17: ='CIRCUIT SIM'!Q703 | BB17: ='CIRCUIT SIM'!S703 | BD17: =IF(OR(AG17:AN17,BA17,BB17),1,AZ17) | BE17: =IF(OR(AG17:AN17,AZ17,BB17),1,BA17) | BF17: =IF(OR(AG17:AN17,AZ17:BA17),1,BB17)
U18: level 3 | V18: =IF(AND(V15>=V14+2.5,V15<V14+3.5),1,0) | AE18: 9 | AF18: Command_FAD_2 | AG18: =R311 | AH18: =R292 | AI18: =R114 | AJ18: =S114 | AM18: =R156 | AO18: =AG18 | AP18: =IF(AG18,1,AH18) | AQ18: =IF(OR(AG18:AH18),1,AI18) | AR18: =IF(OR(AG18:AI18),1,AJ18) | AS18: =IF(OR(AG18:AJ18),1,AK18) | AT18: =IF(OR(AG18:AK18),1,AL18) | AU18: =IF(OR(AG18:AL18),1,AM18) | AV18: =IF(OR(AG18:AM18),1,AN18) | AY18: Command_FAD_2 | AZ18: ='CIRCUIT SIM'!L704 | BA18: ='CIRCUIT SIM'!Q704 | BB18: ='CIRCUIT SIM'!S704 | BD18: =IF(OR(AG18:AN18,BA18,BB18),1,AZ18) | BE18: =IF(OR(AG18:AN18,AZ18,BB18),1,BA18) | BF18: =IF(OR(AG18:AN18,AZ18:BA18),1,BB18)
U19: level 4 | V19: =IF(AND(V15>=V14+3.5,V15<V14+4.5),1,0) | AE19: 10 | AF19: HVAC1_SAF1 | AG19: =R312 | AH19: =R293 | AI19: =P110 | AJ19: =Q110 | AM19: =R156 | AO19: =AG19 | AP19: =IF(AG19,1,AH19) | AQ19: =IF(OR(AG19:AH19),1,AI19) | AR19: =IF(OR(AG19:AI19),1,AJ19) | AS19: =IF(OR(AG19:AJ19),1,AK19) | AT19: =IF(OR(AG19:AK19),1,AL19) | AU19: =IF(OR(AG19:AL19),1,AM19) | AV19: =IF(OR(AG19:AM19),1,AN19) | AY19: HVAC1_SAF1 | AZ19: ='CIRCUIT SIM'!L705 | BA19: ='CIRCUIT SIM'!Q705 | BB19: ='CIRCUIT SIM'!S705 | BD19: =IF(OR(AG19:AN19,BA19,BB19),1,AZ19) | BE19: =IF(OR(AG19:AN19,AZ19,BB19),1,BA19) | BF19: =IF(OR(AG19:AN19,AZ19:BA19),1,BB19)
U20: level 5 | V20: =IF(AND(V15>=V14+4.5,V15<V14+5.5),1,0) | AE20: 11 | AF20: HVAC1_SAF2 | AG20: =R313 | AH20: =R294 | AI20: =P111 | AJ20: =Q111 | AM20: =R156 | AO20: =AG20 | AP20: =IF(AG20,1,AH20) | AQ20: =IF(OR(AG20:AH20),1,AI20) | AR20: =IF(OR(AG20:AI20),1,AJ20) | AS20: =IF(OR(AG20:AJ20),1,AK20) | AT20: =IF(OR(AG20:AK20),1,AL20) | AU20: =IF(OR(AG20:AL20),1,AM20) | AV20: =IF(OR(AG20:AM20),1,AN20) | AY20: HVAC1_SAF2 | AZ20: ='CIRCUIT SIM'!L706 | BA20: ='CIRCUIT SIM'!Q706 | BB20: ='CIRCUIT SIM'!S706 | BD20: =IF(OR(AG20:AN20,BA20,BB20),1,AZ20) | BE20: =IF(OR(AG20:AN20,AZ20,BB20),1,BA20) | BF20: =IF(OR(AG20:AN20,AZ20:BA20),1,BB20)
A21: HVAC LFD's | U21: level 6 | V21: =IF(AND(V15>=V14+5.5,V15<V14+6.5),1,0) | AE21: 12 | AF21: Command_Heater | AY21: Command_Heater
U22: level 7 | V22: =IF(AND(V15>=V14+6.5,V15<V14+7.5),1,0) | AE22: 13 | AF22: Command_Liquidline Solenoid 1 | AY22: Command_Liquidline Solenoid 1
A23: 1. HVAC fresh air damper | U23: level 8 | V23: =IF(V15>=V14+7.5,1,0) | AE23: 14 | AF23: Command_Liquidline Solenoid 2 | AY23: Command_Liquidline Solenoid 2
A24: 1 | B24: External_smoke_detected | F24: ='DATA TRANSFER'!F29 | R24: =IF(AND(D24:Q24),1,0) | AE24: 15 | AF24: Emergency Inverter | AY24: Emergency Inverter
A25: 2 | B25: Driver_Close_command | F25: =HVAC_IOs!D23 | R25: =IF(AND(F25:Q25),1,0) | AE25: 16
A26: 3 | B26: Internal_Smoke_Detected | F26: ='DATA TRANSFER'!F28 | R26: =IF(AND(D26:Q26),1,0)
H27: =IF(OR(F24:F26),1,0) | R27: =IF(AND(F27:Q27),1,0)
A28: 4 | B28: Driver_by_pass_command | F28: 0 | G28: =IF(NOT(F28),1,0) | R28: =IF(AND(D28:Q28),1,0)
A29: 5 | B29: FADR_closed | F29: =Calculation!B28 | R29: =IF(AND(F29:Q29),1,0)
A30: 6 | B30: Fresh_air_Damper_Close(FAD) | H30: =IF(AND(H27,G28,F29),1,0) | R30: =IF(AND(D30:Q30),1,0)
A34: 2. HVAC emergency ventilation Control
A35: 1 | B35: APS1_healthy | F35: =HVAC_IOs!D15 | G35: =IF(NOT(F35),1,0) | R35: =IF(AND(F35:Q35),1,0)
A36: 2 | B36: APS2_Healthy | F36: =HVAC_IOs!D26 | G36: =IF(NOT(F36),1,0) | R36: =IF(AND(F36:Q36),1,0)
B37: LFC05 | H37: =IF(OR(G35:G36),1,0)
A38: 3 | B38: 110V_Battery_supply | F38: =HVAC_IOs!D25 | R38: =IF(AND(F38:Q38),1,0)
A39: 4 | B39: APS1_healthy | F39: =F35 | G39: =IF(NOT(F39),1,0) | R39: =IF(AND(F39:Q39),1,0)
A40: 5 | B40: APS2_healthy | F40: =F36 | G40: =IF(NOT(F40),1,0) | R40: =IF(AND(F40:Q40),1,0)
B41: LFC11 | H41: =IF(AND(F38,G39:G40),1,0)
A42: 6 | B42: VDU command | F42: =HVAC_IOs!D27 | R42: =IF(AND(F42:Q42),1,0)
A43: 7 | B43: HVAC system status | F43: =IF(Calculation!B56=1,0,1) | R43: =IF(AND(F43:Q43),1,0)
A44: 8 | B44: Emergency ventilation | I44: =IF(OR(H37,H41,F42),1,0) | R44: =IF(AND(F44:Q44),1,0)
...

Sheet LFD New
A1: SR No. | B1: INPUTS TO LFD | C1: SOURCE | D1: STATUS
A2: 1 | B2: HVAC 1 ON | D2: 1
B3: HVAC 2 ON | D3: 1
J4: {=IF(OR('Mode Logic'!J6:J10=1),1,0)}
A6: 2 | B6: APS1_healthy | D6: 0
A7: 3 | B7: APS2_Healthy | D7: 0
A8: 4 | B8: 110V_Battery_supply | D8: 1
A9: 5 | B9: VDU command
A10: 6 | B10: HVAC system status
A11: 7 | B11: HVAC1_SMDR_de-energized
A12: 8 | B12: HVAC2_SMDR_de-energized
A13: 9 | B13: SMRR_relay_reset
A14: 10 | B14: TCMS Start allow
A15: 11 | B15: APS_1 failure | D15: =IF(NOT(D6),1,0)
A16: 12 | B16: =IF(Calculation!B35>Calculation!B33,1,0) | D16: =IF(NOT(D7),1,0)
A17: 13 | B17: HVAC_priority_Select
B18: HVAC_AUTO_Mode_TCMS | D18: 1
B19: PPR_High | D19: 1 | O19: =IF(OR('Mode Logic'!J3:J4),1,0)
B20: Comp_min._OFF_timer_expired | D20: 1
B21: No_condenser_fan1_failure | C21: =IF(OR('Mode Logic'!J3,'Mode Logic'!J12),1,0) | D21: 1
B22: No_condenser_fan2_failure | D22: 1
B23: Compressor Set Enabled | D23: 1
B24: Comp start not inhibited by start perm | D24: 1
B25: CTMC_energized_condenser_fan_START | D25: 1
B26: Liquid_line_solenoid_valve_open | D26: 1
B27: CFMC_feedback_OK | D27: 1
B28: CMC_energized | D28: 1
B29: Cooling_demand_>_2nd_comp._threshold | D29: =IF(OR('Mode Logic'!J7:J10),1,0)
B30: 2nd_comp._required | D30: =D29
B31: Comp.start-_allowed | D31: 1
B32: CFM fan OK | D32: 1
B33: HVAC_enable | D33: 1
B34: Motor_01_OK | D34: 1
B35: CB_healthy | D35: 1
B36: NOT_shut_down | D36: 1
B37: Minimum_ON_timer_(60 sec) | D37: 0
B38: Auto_mode_from_TCMS | D38: {=IF(OR('Mode Logic'!J6:J10=1),1,0)}
B39: Stand_by_mode_ON | D39: 1
B40: APS_load_reduction_ON | D40: 1
B41: LVPS_load_shed_ON | D41: 1
...

Sheet CIRCUIT SIM
A1: Sr. No. | B1: Physical location | C1: Component Name | D1: Logical Condition | J1: Condition 1 | P1: Sr. No. | Q1: Physical location | R1: Component Name | S1: Logical Condition | Y1: Condition 1 | AF1: Sr. No. | AG1: Physical location | AH1: Component Name | AI1: Logical Condition | AO1: Condition 1 | AS1: Sr. No. | AT1: Physical location | AU1: Component Name | AV1: Logical Condition | BB1: Condition 1 | BI1: Sr. No. | BJ1: Physical location | BK1: Component Name | BL1: Logical Condition | BR1: Condition 1 | BX1: Sr. No. | BY1: Physical location | BZ1: Component Name | CA1: Logical Condition | CG1: Condition 1 | CI1: Sr. No. | CJ1: Physical location | CK1: Component Name | CL1: Logical Condition | CR1: Condition 1 | CY1: Sr. No. | CZ1: Physical location | DA1: Component Name | DB1: Logical Condition - External circuit | DH1: Condition 1 | DK1: Sr. No. | DL1: Physical location | DM1: Component Name | DN1: Logical Condition - Internal circuit | DT1: Condition 1 | DZ1: Sr. No. | EA1: Physical location | EB1: Component Name | EC1: Logical Condition - internal Circuit | EI1: Condition 1 | EO1: Sr. No. | EP1: Physical location | EQ1: Component Name | ER1: Logical Condition - 14 | EX1: Condition 1 | FE1: Sr. No. | FF1: Physical location | FG1: Component Name | FH1: Logical Condition - External circuit | FN1: Condition 1 | FT1: Sr. No. | FU1: Physical location | FV1: Component Name | FW1: Logical Condition - NO | GC1: Condition 1 | GF1: Sr. No. | GG1: Physical location | GH1: Component Name | GI1: Logical Condition - External circuit | GO1: Condition 1 | GU1: Sr. No. | GV1: Physical location | GW1: Component Name | GX1: Logical Condition - External circuit | HD1: Condition 1 | HK1: Sr. No. | HL1: Physical location | HM1: Component Name | HN1: Logical Condition - External circuit | HZ1: Sr. No. | IA1: Physical location | IB1: Component Name | IC1: Logical Condition - NO 13 | II1: Condition 1 | IL1: Sr. No. | IM1: Physical location | IN1: Component Name | IO1: Logical Condition - External circuit | IU1: Condition 1 | IX1: Sr. No. | IY1: Physical location | IZ1: Component Name | JA1: Logical Condition - External circuit | JN1: Sr. No. | JO1: Physical location | JP1: Component Name | JQ1: Logical Condition - External circuit | JW1: Condition 1 | JZ1: Sr. No. | KA1: Physical location | KB1: Component Name | KI1: Condition 1 | KP1: Sr. No. | KQ1: Physical location | KR1: Component Name | KS1: Logical Condition - External circuit | KY1: Condition 1 | LB1: Sr. No. | LC1: Physical location | LD1: Component Name | LE1: Logical Condition - AS PER INTERNAL CKT NO 11 | LK1: Condition 1 | LR1: Sr. No. | LS1: Physical location | LT1: Component Name | LU1: Logical Condition - NO 12 | MA1: Condition 1 | MH1: Sr. No. | MI1: Physical location | MJ1: Component Name | MQ1: Condition 1
