Workbook
Name A1J: 'CIRCUIT SIMULATION'!$DS$895

Sheet DATA TRANSFER
A816: Unity_DS3D (CPU_WS)
A819: Unity INPUTS from DS3D | I819: OUTPUT TO DS3D | R819: TO UNITY
A820: SR.No | B820: Variable | C820: Labels | D820: Units | E820: Data Type | F820: Value | G820: Remark | I820: SR.No | J820: Variable | K820: Labels | L820: Units | M820: Data Type | N820: Value | O820: Remark | P820: Do not touch | R820: Requirement | S820: Remarks
A821: 1 | B821: Active_Fault_Status | C821: Active Fault Status | D821: Code | E821: Integer | F821: 1 | G821: If Fault is active: 1, Fault Inactive: 0 | I821: 1 | J821: BlueArrowOut | K821: Fresh Air arrow | L821: Fresh Air blue arrow | M821: Integer | N821: 5 | O821: 0-10 (Speed) | P821: =IF('Mode Logic'!V18=1,5,0) | R821: Every Arrow with Speed
A822: 2 | B822: Current_Step_Number | C822: Current Step Number | D822: Step | E822: Integer | F822: 1 | G822: 1-based step index in procedure (0 = reset/unstarted) | I822: 2 | J822: Fan1 | K822: Condensor Fan RedArrow Set 1 | L822: Condensor Fan RedArrow Set 1 | M822: Integer | N822: 5 | O822: 0-10 (Speed) | P822: =IF('Mode Logic'!T18=1,5,0) | R822: Every Arrow Colour Control
A823: 3 | B823: Total_Steps | C823: Total Steps in Procedure | D823: Steps | E823: Integer | F823: 15 | G823: Total steps for active fault | I823: 3 | J823: Fan2 | K823: Evaporator Fan RedArrow Set 2 | L823: Evaporator Fan RedArrow Set 2 | M823: Integer | N823: 5 | O823: 0-10 (Speed) | P823: =IF('Mode Logic'!U18=1,5,0) | R823: Application Quit
A824: 4 | B824: Wrong_Attempts | C824: Wrong Attempts Counter | D824: Count | E824: Integer | F824: 0 | G824: Total number of times wrong steps were taken | I824: 4 | J824: GreenArrowIN1 | K824: Fresh Air Damper Right | L824: Fresh Air Damper Right | M824: Integer | N824: 0 | O824: 0-10 (Speed) | P824: =IF('Mode Logic'!P18=1,5,0) | R824: Fresh Air Damper Left Position
A825: 5 | B825: Fault_101_Status | C825: Fault 101: No HVAC operations | D825: State | E825: Boolean | F825: 0 | G825: 0: Inactive, 1: Active (14 steps) | I825: 5 | J825: GreenArrowIN2 | K825: Fresh Air Damper left | L825: Fresh Air Damper left | M825: Integer | N825: 0 | O825: 0-10 (Speed) | P825: =IF('Mode Logic'!P18=1,5,0) | R825: Fresh Air Damper Right Position
A826: 6 | B826: Fault_102_Status | C826: Fault 102: No ventilation | D826: State | E826: Boolean | F826: 0 | G826: 0: Inactive, 1: Active (22 steps) | I826: 6 | J826: YellowArrowIn | K826: Return Air Damper | L826: Return Air Damper | M826: Integer | N826: 5 | O826: 0-10 (Speed) | P826: =IF('Mode Logic'!Q18=1,5,0) | R826: Return Air Damper Position
A827: 7 | B827: Fault_103_Status | C827: Fault 103: Reduced ventilation | D827: State | E827: Boolean | F827: 0 | G827: 0: Inactive, 1: Active (15 steps) | I827: 7 | J827: RedArrow_Inlet | K827: Fresh Air arrow Colour | L827: Intensity | M827: Float | N827: 0 | O827: 0: Red, 1: Green, 2: Yellow, 3: Blue | R827: Fault Code | S827: Code to trigger the repective fault on Unity
A828: 8 | B828: Fault_104_Status | C828: Fault 104: Suction low and discharge low (C1) | D828: State | E828: Boolean | F828: 1 | G828: 0: Inactive, 1: Active (15 steps) | I828: 8 | J828: RedArrow_Outlet | K828: Condensor Fan RedArrow Set 1 Colour | L828: Intensity | M828: Float | N828: 0 | O828: 0: Red, 1: Green, 2: Yellow, 3: Blue | R828: Fault Reset Trigger | S828: Boolean in Excel toReset Entire Screen to Normal Mode
A829: 9 | B829: Fault_105_Status | C829: Fault 105: Suction low and discharge low (C2) | D829: State | E829: Boolean | F829: 0 | G829: 0: Inactive, 1: Active (14 steps) | I829: 9 | J829: BlueArrow_Outlet | K829: Evaporator Fan RedArrow Set 2 Colour | L829: Intensity | M829: Float | N829: 0 | O829: 0: Red, 1: Green, 2: Yellow, 3: Blue | R829: Show Hide Objects
A830: 10 | B830: Fault_106_Status | C830: Fault 106: High suction and high discharge | D830: State | E830: Boolean | F830: 0 | G830: 0: Inactive, 1: Active (26 steps) | I830: 10 | J830: GreenArrow_Inlet | K830: Fresh Air Inlet Color Intensity | L830: Intensity | M830: Float | N830: 0 | O830: 0-10 (Material color lerp) | R830: All Component Highlight | S830: As per discussion
A831: 11 | B831: Fault_107_Status | C831: Fault 107: Compressor not operating | D831: State | E831: Boolean | F831: 0 | G831: 0: Inactive, 1: Active (40 steps) | I831: 11 | J831: YellowArrow_Inlet | K831: Return Air Inlet Color Intensity | L831: Intensity | M831: Float | N831: 0 | O831: 0-10 (Material color lerp)
A832: 12 | B832: Fault_108_Status | C832: Fault 108: Reduced cooling | D832: State | E832: Boolean | F832: 0 | G832: 0: Inactive, 1: Active (33 steps) | I832: 12 | J832: FADL | K832: Fresh Air Damper Left Position | L832: Position | M832: Float | N832: 0 | O832: %
A833: 13 | B833: Fault_109_Status | C833: Fault 109: No Heating | D833: State | E833: Boolean | F833: 0 | G833: 0: Inactive, 1: Active (15 steps) | I833: 13 | J833: FADR | K833: Fresh Air Damper Right Position | L833: Position | M833: Float | N833: 0 | O833: %
A834: 14 | B834: Fault_110_Status | C834: Fault 110: Over Cooling | D834: State | E834: Boolean | F834: 0 | G834: 0: Inactive, 1: Active (8 steps) | I834: 14 | J834: RAD | K834: Return Air Damper Position | L834: Position | M834: Float | N834: 0 | O834: 0 &100%
A835: 15 | B835: Fault_111_Status | C835: Fault 111: Over Heating | D835: State | E835: Boolean | F835: 0 | G835: 0: Inactive, 1: Active (7 steps) | I835: 15 | J835: DS3D_OFF | K835: DS3D Application Quit | L835: DS3D OFF | M835: Integer | N835: 0 | O835: 0: Running, 1: Shutdown
A836: 16 | B836: Fault_112_Status | C836: Fault 112: No emergency ventilation | D836: State | E836: Boolean | F836: 0 | G836: 0: Inactive, 1: Active (14 steps) | I836: 16 | J836: Fault_Code_Trigger | K836: Fault Trigger Scenario Code | L836: Code | M836: Integer | N836: 104 | O836: Active Fault to Unity (101-114 active)
A837: 17 | B837: Fault_113_Status | C837: Fault 113: Smoke identified in saloon | D837: State | E837: Boolean | F837: 0 | G837: 0: Inactive, 1: Active (13 steps) | I837: 17 | J837: Fault_reset | K837: Fault Reset Trigger | L837: Command | M837: Integer | N837: 0 | O837: 0: Idle, 1: Reset
A838: 18 | B838: Fault_114_Status | C838: Fault 114: Compressor / Blower noisy | D838: State | E838: Boolean | F838: 0 | G838: 0: Inactive, 1: Active (36 steps) | I838: 18 | J838: ShowHideObjects | K838: Toggle Component Visibility | L838: State | M838: Boolean | N838: 0 | O838: 0: Hide, 1: Show
A839: 19 | B839: Fault_115_Status | C839: Fault 115: Spare Fault Scenario | D839: State | E839: Boolean | F839: 0 | G839: 0: Inactive, 1: Active (Reserved in Excel) | I839: 19 | J839: Compresor 1_Highlights | K839: Toggle Compressor Highlights Visibility | L839: State | M839: Boolean | N839: 1 | O839: 0: Hide Highlights, 1: Show Highlights
A840: 20 | B840: Fault_116_Status | C840: Fault 116: Spare Fault Scenario | D840: State | E840: Boolean | F840: 0 | G840: 0: Inactive, 1: Active (Reserved in Excel) | I840: 20 | J840: Compresor 2_Highlights | K840: Toggle Compressor Highlights Visibility | L840: State | M840: Boolean | N840: 1 | O840: 0: Hide Highlights, 1: Show Highlights
A841: 21 | C841: Spare | E841: Boolean | I841: 21 | J841: Compresor 3_Highlights | K841: Toggle Compressor Highlights Visibility | L841: State | M841: Boolean | N841: 1 | O841: 0: Hide Highlights, 1: Show Highlights
A842: 22 | C842: Spare | E842: Boolean | I842: 22 | J842: Compresor 4_Highlights | K842: Toggle Compressor Highlights Visibility | L842: State | M842: Boolean | N842: 1 | O842: 0: Hide Highlights, 1: Show Highlights
A843: 23 | C843: Spare | E843: Boolean | I843: 23 | J843: FAT_Sensor_Highlights | K843: Toggle FAT Sensor Highlight Visibility | L843: State | M843: Boolean | N843: 1 | O843: 0: Hide Highlights, 1: Show Highlights (Fresh Air Temp)
A844: 24 | C844: Spare | E844: Boolean | I844: 24 | J844: RAT_Sensor_Highlights | K844: Toggle RAT Sensor Highlight Visibility | L844: State | M844: Boolean | N844: 1 | O844: 0: Hide Highlights, 1: Show Highlights (Return Air Temp)
A845: 25 | C845: Spare | E845: Boolean | I845: 25 | J845: SAT_Sensor_Highlights | K845: Toggle SAT Sensor Highlight Visibility | L845: State | M845: Boolean | N845: 1 | O845: 0: Hide Highlights, 1: Show Highlights (Supply Air Temp)
A846: 26 | C846: Spare | E846: Boolean | I846: 26 | J846: Smoke_Detector_Highlights | K846: Toggle Smoke Detector Highlight Visibility | L846: State | M846: Boolean | N846: 1 | O846: 0: Hide Highlights, 1: Show Highlights (Smoke Detector)
A847: 27 | C847: Spare | E847: Boolean | I847: 27 | J847: Spare Sensor | K847: Spare | M847: Integer | N847: 0
A848: 28 | C848: Spare | E848: Boolean | I848: 28 | J848: Spare Sensor | K848: Spare | M848: Integer | N848: 0
A849: 29 | C849: Spare | E849: Boolean | I849: 29 | K849: Spare | M849: Integer | N849: 0
A850: 30 | C850: Spare | E850: Boolean | I850: 30 | K850: Spare | M850: Integer | N850: 0
A851: 31 | C851: Spare | E851: Boolean | I851: 31 | K851: Spare | M851: Integer | N851: 0
A852: 32 | C852: Spare | E852: Boolean | I852: 32 | K852: Spare | M852: Integer | N852: 0
A853: 33 | C853: Spare | E853: Boolean | I853: 33 | K853: Spare | M853: Integer | N853: 0
A854: 34 | B854: Telemetry_Event | C854: Telemetry Event Name | D854: String | E854: String | F854: fault_started | G854: fault_started / step_completed / fault_completed | I854: 34 | K854: Spare | M854: Integer | N854: 0
I855: 35 | K855: Spare | M855: Integer | N855: 0
I856: 36 | K856: Spare | M856: Integer | N856: 0
I857: 37 | K857: Spare | M857: Integer | N857: 0
...

Sheet Set point Calc
A1: Ambient Temperature | B1: ='DATA TRANSFER'!F39 | E1: Temp | F1: Celcius | G1: Kelvin
A2: Setpoint | B2: ='DATA TRANSFER'!F37 | E2: T1 | F2: 18 | G2: 291.15
A3: RAT | B3: =Calculation!B36 | E3: T2 | F3: 25 | G3: 298.15
E4: T3 | F4: 43 | G4: 316.15
E5: T4 | F5: 10 | G5: 283.15
E6: T5 | F6: 11 | G6: 284.15
E7: T6 | F7: 12 | G7: 285.15
E8: T7 | F8: 30 | G8: 303.15
A12: Set point | B12: Amb<T1 | D12: T1<Amb<T2 | F12: T2<Amb<T3 | H12: Amb>T3 | J12: Final SP Value
B13: Status | C13: SP Value | D13: Status | E13: SP Value | F13: Status | G13: SP Value | H13: Status | I13: SP Value | J13: SP Value
B14: =IF(B1<F2,1,0) | C14: =IF(B1<F2,F2,0) | D14: =IF(AND(B1>F2,B1<F3),1,0) | E14: =IF(D14=1,1*(F3-B1)+18,0) | F14: =IF(AND(B1<F4,B1>F3),1,0) | G14: =IF(AND(B1<F4,B1>F3),F3,0) | H14: =IF(B1>F4,1,0) | I14: =IF(B1>F4,B1-18,0) | J14: =MAX(C14,E14,G14,I14)
A16: Cooling Circuit | B16: Amb<T4 | D16: Amb<T6 | F16: Amb>=T6 | H16: Final Status
B17: Cooling Circuit 1 | C17: Cooling Circuit 2 | D17: Cooling Circuit 1 | E17: Cooling Circuit 2 | F17: Cooling Circuit 1 | G17: Cooling Circuit 2 | H17: Cooling Circuit 1 | I17: Cooling Circuit 2
B18: 0 | C18: 0 | D18: 1 | E18: 0 | F18: 1 | G18: 1 | H18: =IF(OR(AND(B1>F5,B1<F7),B1>F8),1,0) | I18: =IF(B1>F8,1,0)
A21: Heater | B21: Amb<T5 | D21: Amb>T5 | F21: Amb>T7 | H21: Final Status
B22: OH Heater 1 | C22: OH Heater 2 | D22: OH Heater 1 | E22: OH Heater 2 | F22: OH Heater 1 | G22: OH Heater 2 | H22: OH Heater 1 | I22: OH Heater 2
B23: 1 | C23: 1 | D23: 1 | E23: 0 | F23: 0 | G23: 0 | H23: =IF(OR(AND(B1>F6,B1<F8),B1<F6),1,0) | I23: =IF(B1<F6,1,0)
DL171: ='DATA TRANSFER'!F37

Sheet Fault Logic
E1: =E2 | J1: =J2 | O1: =O2 | T1: =T2 | Y1: =Y2 | AD1: =AD2 | AI1: =AI2 | AN1: =AN2 | AS1: =AS2 | AX1: =AX2 | BC1: =BC2 | BH1: =BH2 | BM1: =BM2 | BR1: =BR2
B2: Components | C2: Status | E2: Fault 101 | F2: No HVAC Operation | G2: Steps Complete | H2: 4 | J2: Fault 102 | K2: No Ventilation | L2: Steps Complete | M2: 0 | O2: Fault 103 | P2: Reduced Ventilation | Q2: Steps Complete | R2: 8 | T2: Fault 104 | U2: Suction low and discharge low | V2: Steps Complete | W2: 1 | Y2: Fault 105 | Z2: Suction low and discharge low | AA2: Steps Complete | AB2: 8 | AD2: Fault 106 | AE2: High suction and high discharge | AF2: Steps Complete | AG2: 8 | AI2: Fault 107 | AJ2: Compressor not Operating | AK2: Steps Complete | AL2: 8 | AN2: Fault 108 | AO2: Reduced Cooling | AP2: Steps Complete | AQ2: 8 | AS2: Fault 109 | AT2: No Heating | AU2: Steps Complete | AV2: 8 | AX2: Fault 110 | AY2: Overcooling | AZ2: Steps Complete | BA2: 8 | BC2: Fault 111 | BD2: Overheating | BE2: Steps Complete | BF2: 8 | BH2: Fault 112 | BI2: No Emergency Ventilation | BJ2: Steps Complete | BK2: 8 | BM2: Fault 113 | BN2: Smoke Identified in Saloon | BO2: Steps Complete | BP2: 8 | BR2: Fault 114 | BS2: Compressor is excessively noisy | Condenser Fan or Supply air Blower is excessively noisy | Noisy TX valve | HVAC unit is noisy | BT2: Steps Complete | BU2: 2
B3: HVAC OFF | E3: Cause 1 | F3: =_xlfn.CONCAT("Faulty"," ",F26) | G3: =IF(H4=1,1,0) | H3: Cause Triggered | J3: Cause 1 | K3: =_xlfn.CONCAT("Faulty"," ",K34) | L3: =IF(M4=1,1,0) | M3: Cause Triggered | O3: Cause 1 | P3: =_xlfn.CONCAT("Faulty"," ",P27) | Q3: =IF(R4=1,1,0) | R3: Cause Triggered | T3: Cause 1 | U3: =U27 | V3: =IF(W4=1,1,0) | W3: Cause Triggered | Y3: Cause 1 | Z3: =_xlfn.CONCAT(Z26," ","Faulty") | AA3: =IF(AB4=1,1,0) | AB3: Cause Triggered | AD3: Cause 1 | AE3: =_xlfn.CONCAT(AE40," ","Faulty") | AF3: =IF(AG4=1,1,0) | AG3: Cause Triggered | AI3: Cause 1 | AJ3: =_xlfn.CONCAT(AJ59," ","Faulty") | AK3: =IF(AL4=1,1,0) | AL3: Cause Triggered | AN3: Cause 1 | AO3: =_xlfn.CONCAT(AO58," ","Faulty") | AP3: =IF(AQ4=1,1,0) | AQ3: Cause Triggered | AS3: Cause 1 | AT3: =_xlfn.CONCAT(AT34," ","Faulty") | AU3: =IF($AV$4=1,1,0) | AV3: Cause Triggered | AX3: Cause 1 | AY3: =_xlfn.CONCAT(AY27," ","Faulty") | AZ3: =IF(BA4=1,1,0) | BA3: Cause Triggered | BC3: Cause 1 | BD3: =_xlfn.CONCAT(BD21," ","Faulty") | BE3: =IF(BF4=1,1,0) | BF3: Cause Triggered | BH3: Cause 1 | BI3: =_xlfn.CONCAT(BI27," ","Faulty") | BJ3: =IF(BK4=1,1,0) | BK3: Cause Triggered | BM3: Cause 1 | BN3: =_xlfn.CONCAT(BN25," ","Faulty") | BO3: =IF(BP4=1,1,0) | BP3: Cause Triggered | BR3: Cause 1 | BS3: =_xlfn.CONCAT(BS85," ","Faulty") | BT3: =IF($BU$4=1,1,0) | BU3: Cause Triggered
B4: Control Panel Circuit Breakers | E4: Cause 2 | F4: =_xlfn.CONCAT("Faulty"," ",F27) | G4: =IF(H4=2,1,0) | H4: 1 | J4: Cause 2 | K4: =_xlfn.CONCAT("Faulty"," ",K35) | L4: =IF(M4=2,1,0) | M4: 1 | O4: Cause 2 | P4: =_xlfn.CONCAT("Faulty"," ",P28) | Q4: =IF(R4=2,1,0) | R4: 0 | T4: Cause 2 | U4: =_xlfn.CONCAT(U28," ","Faulty") | V4: =IF(W4=2,1,0) | W4: 1 | Y4: Cause 2 | Z4: =_xlfn.CONCAT(Z27," ","Faulty") | AA4: =IF(AB4=2,1,0) | AB4: 0 | AD4: Cause 2 | AE4: =_xlfn.CONCAT(AE41," ","Faulty") | AF4: =IF($AG$4=2,1,0) | AG4: 0 | AI4: Cause 2 | AJ4: =_xlfn.CONCAT(AJ60," ","Faulty") | AK4: =IF(AL4=2,1,0) | AL4: 0 | AN4: Cause 2 | AO4: =_xlfn.CONCAT(AO59," ","Damaged") | AP4: =IF($AQ$4=2,1,0) | AQ4: 0 | AS4: Cause 2 | AT4: =_xlfn.CONCAT(AT35," ","Faulty") | AU4: =IF($AV$4=2,1,0) | AV4: 0 | BA4: 0 | BC4: Cause 2 | BD4: =_xlfn.CONCAT(BD22," ","Faulty") | BE4: =IF(BF4=2,1,0) | BF4: 0 | BK4: 0 | BM4: Cause 2 | BN4: =_xlfn.CONCAT(BN26," ","Faulty") | BO4: =IF(BP4=2,1,0) | BP4: 0 | BR4: Cause 2 | BS4: =_xlfn.CONCAT(BS86," ","Faulty") | BT4: =IF($BU$4=1,1,0) | BU4: 0
B5: Supply Air Fan | J5: Cause 3 | K5: =_xlfn.CONCAT("Faulty"," ",K36) | L5: =IF(M4=3,1,0) | O5: Cause 3 | P5: Refrigerant Leak | Q5: =IF(R4=3,1,0) | AD5: Cause 3 | AE5: =_xlfn.CONCAT(AE42," ","Faulty") | AF5: =IF($AG$4=3,1,0) | AI5: Cause 3 | AJ5: =_xlfn.CONCAT(AJ61," ","Faulty") | AK5: =IF(AL4=3,1,0) | AN5: Cause 3 | AO5: =_xlfn.CONCAT(AO60," ","Faulty") | AP5: =IF($AQ$4=3,1,0) | AS5: Cause 3 | AT5: =_xlfn.CONCAT(AT36," ","Faulty") | AU5: =IF($AV$4=3,1,0) | BR5: Cause 3 | BS5: =_xlfn.CONCAT(BS87," ","Faulty") | BT5: =IF($BU$4=3,1,0)
B6: =K36 | E6: Sr No | F6: Fault Step | G6: Step Status | H6: Remarks | J6: Sr No | K6: Fault Step | L6: Step Status | M6: Remarks | O6: Sr No | P6: Fault Step | Q6: Step Status | R6: Remarks | T6: Sr No | U6: Fault Step | V6: Step Status | W6: Remarks | Y6: Sr No | Z6: Fault Step | AA6: Step Status | AB6: Remarks | AD6: Cause 4 | AE6: =_xlfn.CONCAT(AE43," ","Faulty") | AF6: =IF($AG$4=4,1,0) | AI6: Sr No | AJ6: Fault Step | AK6: Step Status | AL6: Remarks | AN6: Cause 4 | AO6: =_xlfn.CONCAT(AO61," ","Damaged") | AP6: =IF($AQ$4=4,1,0) | AS6: Cause 4 | AT6: =AT37 | AU6: =IF($AV$4=4,1,0) | AX6: Sr No | AY6: Fault Step | AZ6: Step Status | BA6: Remarks | BC6: Sr No | BD6: Fault Step | BE6: Step Status | BF6: Remarks | BH6: Sr No | BI6: Fault Step | BJ6: Step Status | BK6: Remarks | BM6: Sr No | BN6: Fault Step | BO6: Step Status | BP6: Remarks | BR6: Cause 4 | BS6: =_xlfn.CONCAT(BS88," ","Faulty") | BT6: =IF($BU$4=4,1,0)
B7: Compressor | C7: 1 | E7: 1 | F7: Loosen and remove 24 nos M8X20 bolts (8) along with washer set (7) to open evaporator cover (9). (Spanner) | G7: =IF($H$2>=E7,1,0) | H7: 1: Complete, 0: Incomplete | J7: 1 | K7: Loosen and remove 24 nos M8X20 bolts (8) along with washer set (7) to open evaporator cover (9). (Spanner) | L7: =IF($M$2>=J7,1,0) | M7: 1: Complete, 0: Incomplete | O7: 1 | P7: Loosen and remove 24 nos M8X20 bolts (8) along with washer set (7) to open evaporator cover (9). (Spanner) | Q7: =IF($R$2>=O7,1,0) | R7: 1: Complete, 0: Incomplete | T7: 1 | U7: Loosen and remove 24 nos M8X20 bolts (8) along with washer set (7) to open evaporator cover (9). (Spanner) | V7: =IF($W$2>=T7,1,0) | W7: 1: Complete, 0: Incomplete | Y7: 1 | Z7: Remove Condenser Mesh with lifting device (Lifting Device) | AA7: =IF($AB$2>=Y7,1,0) | AB7: 1: Complete, 0: Incomplete | AD7: Sr No | AE7: Fault Step | AF7: Step Status | AG7: Remarks | AI7: 1 | AJ7: Loosen and remove 24 nos M8X20 bolts (8) along with washer set (7) to open evaporator cover (9). (Spanner) | AK7: =IF($AL$2>=AI7,1,0) | AL7: 1: Complete, 0: Incomplete | AN7: Cause 5 | AO7: =_xlfn.CONCAT(AO62," ","Faulty") | AP7: =IF($AQ$4=5,1,0) | AS7: Cause 5 | AT7: =_xlfn.CONCAT(AT38," ","Faulty") | AU7: =IF($AV$4=5,1,0) | AX7: 1 | AY7: Loosen and remove 24 nos M8X20 bolts (8) along with washer set (7) to open evaporator cover (9). (Spanner) | AZ7: =IF($BA$2>=AX7,1,0) | BA7: 1: Complete, 0: Incomplete | BC7: 1 | BD7: Loosen and remove 24 nos M8X20 bolts (8) along with washer set (7) to open evaporator cover (9). (Spanner) | BE7: =IF(BF$2>=BC7,1,0) | BF7: 1: Complete, 0: Incomplete | BH7: 1 | BI7: Loosen and remove 24 nos M8X20 bolts (8) along with washer set (7) to open evaporator cover (9). (Spanner) | BJ7: =IF($BK$2>=BH7,1,0) | BK7: 1: Complete, 0: Incomplete | BM7: 1 | BN7: Loosen and remove 24 nos M8X20 bolts (8) along with washer set (7) to open evaporator cover (9). (Spanner) | BO7: =IF($BP$2>=BM7,1,0) | BP7: 1: Complete, 0: Incomplete | BR7: Cause 5 | BS7: =_xlfn.CONCAT(BS89," ","Faulty") | BT7: =IF($BU$4=5,1,0)
B8: Supply Air Fan Circuit | E8: =E7+1 | F8: Remove hinge pins to remove the evaporator cover (9) from HVAC unit. (Pliers) | G8: =IF($H$2>=E8,1,0) | J8: =J7+1 | K8: Remove hinge pins to remove the evaporator cover (9) from HVAC unit. (Pliers) | L8: =IF($M$2>=J8,1,0) | O8: =O7+1 | P8: Remove hinge pins to remove the evaporator cover (9) from HVAC unit. (Pliers) | Q8: =IF($R$2>=O8,1,0) | T8: =T7+1 | U8: Remove hinge pins to remove the evaporator cover (9) from HVAC unit. (Pliers) | V8: =IF($W$2>=T8,1,0) | Y8: =Y7+1 | Z8: Remove Condenser Coil & Filter with lifting device (Lifting Device) | AA8: =IF($AB$2>=Y8,1,0) | AD8: 1 | AE8: Unscrew Fan cover bolt (Spanner) | AF8: =IF($AG$2>=AD8,1,0) | AG8: 1: Complete, 0: Incomplete | AI8: =AI7+1 | AJ8: Remove hinge pins to remove the evaporator cover (9) from HVAC unit. (Pliers) | AK8: =IF($AL$2>=AI8,1,0) | AN8: Cause 6 | AO8: =_xlfn.CONCAT(AO63," ","Faulty") | AP8: =IF($AQ$4=6,1,0) | AS8: Sr No | AT8: Fault Step | AU8: Step Status | AV8: Remarks | AX8: =AX7+1 | AY8: Remove hinge pins to remove the evaporator cover (9) from HVAC unit. (Pliers) | AZ8: =IF($BA$2>=AX8,1,0) | BC8: =BC7+1 | BD8: Remove hinge pins to remove the evaporator cover (9) from HVAC unit. (Pliers) | BE8: =IF(BF$2>=BC8,1,0) | BH8: =BH7+1 | BI8: Remove hinge pins to remove the evaporator cover (9) from HVAC unit. (Pliers) | BJ8: =IF($BK$2>=BH8,1,0) | BM8: =BM7+1 | BN8: Remove hinge pins to remove the evaporator cover (9) from HVAC unit. (Pliers) | BO8: =IF($BP$2>=BM8,1,0) | BR8: Cause 6 | BS8: =_xlfn.CONCAT(BS90," ","Faulty") | BT8: =IF($BU$4=6,1,0)
B9: Supply Air Filter | E9: =E8+1 | F9: Remove the evaporator cover (9) from HVAC unit using suitable lifting device. (None) | G9: =IF($H$2>=E9,1,0) | J9: =J8+1 | K9: Remove the evaporator cover (9) from HVAC unit using suitable lifting device. (None) | L9: =IF($M$2>=J9,1,0) | O9: =O8+1 | P9: Remove the evaporator cover (9) from HVAC unit using suitable lifting device. (None) | Q9: =IF($R$2>=O9,1,0) | T9: =T8+1 | U9: Remove the evaporator cover (9) from HVAC unit using suitable lifting device. (None) | V9: =IF($W$2>=T9,1,0) | Y9: =Y8+1 | Z9: Check for leaks using Electronic leak detector (Electronic Leak Detector) | AA9: =IF($AB$2>=Y9,1,0) | AD9: =AD8+1 | AE9: Open fan cover (Insulated Gloves) | AF9: =IF($AG$2>=AD9,1,0) | AI9: =AI8+1 | AJ9: Remove the evaporator cover (9) from HVAC unit using suitable lifting device. (None) | AK9: =IF($AL$2>=AI9,1,0) | AN9: Sr No | AO9: Fault Step | AP9: Step Status | AQ9: Remarks | AS9: 1 | AT9: Loosen and remove 24 nos M8X20 bolts (8) along with washer set (7) to open evaporator cover (9). (Spanner) | AU9: =IF($AV$2>=AS9,1,0) | AV9: 1: Complete, 0: Incomplete | AX9: =AX8+1 | AY9: Remove the evaporator cover (9) from HVAC unit using suitable lifting device. (None) | AZ9: =IF($BA$2>=AX9,1,0) | BC9: =BC8+1 | BD9: Remove the evaporator cover (9) from HVAC unit using suitable lifting device. (None) | BE9: =IF(BF$2>=BC9,1,0) | BH9: =BH8+1 | BI9: Remove the evaporator cover (9) from HVAC unit using suitable lifting device. (None) | BJ9: =IF($BK$2>=BH9,1,0) | BM9: =BM8+1 | BN9: Remove the evaporator cover (9) from HVAC unit using suitable lifting device. (None) | BO9: =IF($BP$2>=BM9,1,0) | BR9: Cause 7 | BS9: =_xlfn.CONCAT(BS91," ","Faulty") | BT9: =IF($BU$4=7,1,0)
B10: Evaporator Coil Damage | E10: =E9+1 | F10: Remove electrical control panel assembly (Spanner) | G10: =IF($H$2>=E10,1,0) | J10: =J9+1 | K10: Remove electrical control panel assembly (Spanner) | L10: =IF($M$2>=J10,1,0) | O10: =O9+1 | P10: Open supply air blower (Spanner) | Q10: =IF($R$2>=O10,1,0) | T10: =T9+1 | U10: Check the evaporator coil (1) for any damages to the fins. (Visual Inspection Lamp) | V10: =IF($W$2>=T10,1,0) | Y10: =Y9+1 | Z10: Open Filter Drier Cover (Screwdriver) | AA10: =IF($AB$2>=Y10,1,0) | AD10: =AD9+1 | AE10: Unscrews Fan Motor Bolt (Spanner) | AF10: =IF($AG$2>=AD10,1,0) | AI10: =AI9+1 | AJ10: Remove electrical control panel assembly (Spanner) | AK10: =IF($AL$2>=AI10,1,0) | AN10: 1 | AO10: Unscrew bottom panel (Spanner) | AP10: =IF($AQ$2>=AN10,1,0) | AQ10: 1: Complete, 0: Incomplete | AS10: =AS9+1 | AT10: Remove hinge pins to remove the evaporator cover (9) from HVAC unit. (Pliers) | AU10: =IF($AV$2>=AS10,1,0) | AX10: =AX9+1 | AY10: Open supply air cover (Spanner) | AZ10: =IF($BA$2>=AX10,1,0) | BC10: =BC9+1 | BD10: Check the temperature sensors for any damage (Clamp Thermometer) | BE10: =IF(BF$2>=BC10,1,0) | BH10: =BH9+1 | BI10: Remove electrical control panel assembly (Spanner) | BJ10: =IF($BK$2>=BH10,1,0) | BM10: =BM9+1 | BN10: Remove the fresh air dampers (Spanner) | BO10: =IF($BP$2>=BM10,1,0) | BR10: Cause 8 | BS10: =_xlfn.CONCAT(BS92," ","Faulty") | BT10: =IF($BU$4=8,1,0)
B11: TX Valve | E11: =E10+1 | F11: Check all circuit breakers and close. (Multimeter) | G11: =IF($H$2>=E11,1,0) | J11: =J10+1 | K11: Check all circuit breakers and close. (Multimeter) | L11: =IF($M$2>=J11,1,0) | O11: =O10+1 | P11: Clean the supply air blower (1) with compressed air. (Compressed Air Gun) | Q11: =IF($R$2>=O11,1,0) | T11: =T10+1 | U11: Check and defrost evaporator coil. (Visual Inspection) | V11: =IF($W$2>=T11,1,0) | Y11: =Y10+1 | Z11: Remove Filter Drier (Insulated Gloves) | AA11: =IF($AB$2>=Y11,1,0) | AD11: =AD10+1 | AE11: Remove Fan Motor (Insulated Gloves) | AF11: =IF($AG$2>=AD11,1,0) | AI11: =AI10+1 | AJ11: Check all circuit breakers and close. (Multimeter) | AK11: =IF($AL$2>=AI11,1,0) | AN11: =AN10+1 | AO11: Remove bottom panel (Insulated Gloves) | AP11: =IF($AQ$2>=AN11,1,0) | AS11: =AS10+1 | AT11: Remove the evaporator cover (9) from HVAC unit using suitable lifting device. (None) | AU11: =IF($AV$2>=AS11,1,0) | AX11: =AX10+1 | AY11: Remove FAT Bolt (Spanner) | AZ11: =IF($BA$2>=AX11,1,0) | BC11: =BC10+1 | BD11: RAT Damaged (Visual Inspection) | BE11: =IF(BF$2>=BC11,1,0) | BH11: =BH10+1 | BI11: Check all circuit breakers and close. (Multimeter) | BJ11: =IF($BK$2>=BH11,1,0) | BM11: =BM10+1 | BN11: Replace the fresh air dampers (Visual Inspection) | BO11: =IF($BP$2>=BM11,1,0) | BR11: Cause 9 | BS11: =_xlfn.CONCAT(BS93," ","Faulty") | BT11: =IF($BU$4=9,1,0)
B12: Filter Drier | E12: =E11+1 | F12: Unplug the connected wires (Screwdriver) | G12: =IF($H$2>=E12,1,0) | J12: =J11+1 | K12: Unplug the connected wires (Screwdriver) | L12: =IF($M$2>=J12,1,0) | O12: =O11+1 | P12: Rotate supply air blower (1) motor with hand and ensure that only a light force is required to rotate it. (Insulated Hand Gloves) | Q12: =IF($R$2>=O12,1,0) | T12: =T11+1 | U12: Use a fin comb to straighten any bent fins. (Fin Comb) | V12: =IF($W$2>=T12,1,0) | Y12: =Y11+1 | Z12: Replace Filter Drier (None) | AA12: =IF($AB$2>=Y12,1,0) | AD12: =AD11+1 | AE12: Replace Fan Motor (None) | AF12: =IF($AG$2>=AD12,1,0) | AI12: =AI11+1 | AJ12: Unplug the connected wires (Screwdriver) | AK12: =IF($AL$2>=AI12,1,0) | AN12: =AN11+1 | AO12: Unscrew return air damper (Spanner) | AP12: =IF($AQ$2>=AN12,1,0) | AS12: =AS11+1 | AT12: Remove electrical control panel assembly (Spanner) | AU12: =IF($AV$2>=AS12,1,0) | AX12: =AX11+1 | AY12: Replace with new FAT Sensor (None) | AZ12: =IF($BA$2>=AX12,1,0) | BC12: =BC11+1 | BD12: Unbolt the return air temperature sensor (Spanner) | BE12: =IF(BF$2>=BC12,1,0) | BH12: =BH11+1 | BI12: Unplug the connected wires (Screwdriver) | BJ12: =IF($BK$2>=BH12,1,0) | BM12: =BM11+1 | BN12: Unscrew fresh air filter bolt (Screwdriver) | BO12: =IF($BP$2>=BM12,1,0) | BR12: Sr No | BS12: Fault Step | BT12: Step Status | BU12: Remarks
B13: Condensor Fan Motor | E13: =E12+1 | F13: Remove electrical plugs. (Insulated Gloves) | G13: =IF($H$2>=E13,1,0) | J13: =J12+1 | K13: Remove electrical plugs. (Insulated Gloves) | L13: =IF($M$2>=J13,1,0) | O13: =O12+1 | P13: Remove supply air blower (Screwdriver) | Q13: =IF($R$2>=O13,1,0) | T13: =T12+1 | U13: Wash the evaporator coil (1) with warm to hot water and a small quantity of detergent. The hot water softens the bristles helps the grease to dissolve and removes the chlorides. (Bristle Brush) | V13: =IF($W$2>=T13,1,0) | Y13: =Y12+1 | Z13: Check LP/HP (Manifold Gauge Set) | AA13: =IF($AB$2>=Y13,1,0) | AD13: =AD12+1 | AE13: Clean the condenser fan with dry compressed air (Compressed Air) | AF13: =IF($AG$2>=AD13,1,0) | AI13: =AI12+1 | AJ13: Remove electrical plugs. (Insulated Gloves) | AK13: =IF($AL$2>=AI13,1,0) | AN13: =AN12+1 | AO13: Remove return air damper (Insulated Gloves) | AP13: =IF($AQ$2>=AN13,1,0) | AS13: =AS12+1 | AT13: Check all circuit breakers and close. (Multimeter) | AU13: =IF($AV$2>=AS13,1,0) | AX13: =AX12+1 | AY13: Secure with FAT bolt (None) | AZ13: =IF($BA$2>=AX13,1,0) | BC13: =BC12+1 | BD13: Remove the return air temperature sensor (None) | BE13: =IF(BF$2>=BC13,1,0) | BH13: =BH12+1 | BI13: Remove electrical plugs. (Insulated Gloves) | BJ13: =IF($BK$2>=BH13,1,0) | BM13: =BM12+1 | BN13: Replace fresh air filter (Visual Inspection) | BO13: =IF($BP$2>=BM13,1,0) | BR13: 1 | BS13: Run HVAC 20 mins. (None) | BT13: =IF($BU$2>=BR13,1,0) | BU13: 1: Complete, 0: Incomplete
B14: Condensor Fan Circuit Breaker | E14: =E13+1 | F14: Replace the plugs (Visual Inspection) | G14: =IF($H$2>=E14,1,0) | J14: =J13+1 | K14: Replace the plugs (Visual Inspection) | L14: =IF($M$2>=J14,1,0) | O14: =O13+1 | P14: Replace supply air blower (Visual Inspection) | Q14: =IF($R$2>=O14,1,0) | T14: =T13+1 | U14: Clean the drain tray (2) with wet cloth (Wet Cloth) | V14: =IF($W$2>=T14,1,0) | Y14: =Y13+1 | Z14: Loosen and remove 24 nos M8X20 bolts (8) along with washer set (7) to open evaporator cover (9). (Spanner) | AA14: =IF($AB$2>=Y14,1,0) | AD14: =AD13+1 | AE14: Unscrew condenser fan bolt (Spanner) | AF14: =IF($AG$2>=AD14,1,0) | AI14: =AI13+1 | AJ14: Replace the plugs (Visual Inspection) | AK14: =IF($AL$2>=AI14,1,0) | AN14: =AN13+1 | AO14: Loosen and remove 24 nos M8X20 bolts (8) along with washer set (7) to open evaporator cover (9). (Spanner) | AP14: =IF($AQ$2>=AN14,1,0) | AS14: =AS13+1 | AT14: Unplug the connected wires (Screwdriver) | AU14: =IF($AV$2>=AS14,1,0) | AX14: =AX13+1 | AY14: Remove SAT Bolt (Spanner) | AZ14: =IF($BA$2>=AX14,1,0) | BC14: =BC13+1 | BD14: Replace the return air temperature sensor (None) | BE14: =IF(BF$2>=BC14,1,0) | BH14: =BH13+1 | BI14: Replace the plugs (Visual Inspection) | BJ14: =IF($BK$2>=BH14,1,0) | BM14: =BM13+1 | BN14: Remove fresh air damper motor (Screwdriver) | BO14: =IF($BP$2>=BM14,1,0) | BR14: =BR13+1 | BS14: Unusual noise from compressor assembly (None) | BT14: =IF($BU$2>=BR14,1,0)
B15: Condensor Coil | E15: =E14+1 | F15: Connect the electrical plugs. (Screwdriver) | G15: =IF($H$2>=E15,1,0) | J15: =J14+1 | K15: Connect the electrical plugs. (Screwdriver) | L15: =IF($M$2>=J15,1,0) | O15: =O14+1 | P15: Close air supply blower (Visual Inspection) | Q15: =IF($R$2>=O15,1,0) | T15: =T14+1 | U15: Ensure that there is no condensate or debris left over on the drain tray (2). (Vacuum Cleaner) | V15: =IF($W$2>=T15,1,0) | Y15: =Y14+1 | Z15: Remove hinge pins to remove the evaporator cover (9) from HVAC unit. (Pliers) | AA15: =IF($AB$2>=Y15,1,0) | AD15: =AD14+1 | AE15: Remove condenser fan (Insulated Gloves) | AF15: =IF($AG$2>=AD15,1,0) | AI15: =AI14+1 | AJ15: Connect the electrical plugs. (Screwdriver) | AK15: =IF($AL$2>=AI15,1,0) | AN15: =AN14+1 | AO15: Remove hinge pins to remove the evaporator cover (9) from HVAC unit. (Pliers) | AP15: =IF($AQ$2>=AN15,1,0) | AS15: =AS14+1 | AT15: Remove electrical plugs. (Insulated Gloves) | AU15: =IF($AV$2>=AS15,1,0) | AX15: =AX14+1 | AY15: Remove SAT Sensor (None) | AZ15: =IF($BA$2>=AX15,1,0) | BC15: =BC14+1 | BD15: Secure the RAT sensor bolt (None) | BE15: =IF(BF$2>=BC15,1,0) | BH15: =BH14+1 | BI15: Connect the electrical plugs. (Screwdriver) | BJ15: =IF($BK$2>=BH15,1,0) | BM15: =BM14+1 | BN15: Replace fresh air damper motor (Visual Inspection) | BO15: =IF($BP$2>=BM15,1,0) | BR15: =BR14+1 | BS15: Unscrew bolt compressor unit cover (Spanner) | BT15: =IF($BU$2>=BR15,1,0)
B16: Refrigerent Level | E16: =E15+1 | F16: Close electrical control panel assembly (None) | G16: =IF($H$2>=E16,1,0) | J16: =J15+1 | K16: Close electrical control panel assembly (None) | L16: =IF($M$2>=J16,1,0) | O16: =O15+1 | P16: Unscrew bottom panel (Spanner) | Q16: =IF($R$2>=O16,1,0) | T16: =T15+1 | U16: Remove the grommet on the drain hole cover. (Pliers) | V16: =IF($W$2>=T16,1,0) | Y16: =Y15+1 | Z16: Remove the evaporator cover (9) from HVAC unit using suitable lifting device. (None) | AA16: =IF($AB$2>=Y16,1,0) | AD16: =AD15+1 | AE16: Replace condenser fan (None) | AF16: =IF($AG$2>=AD16,1,0) | AI16: =AI15+1 | AJ16: Close electrical control panel assembly (None) | AK16: =IF($AL$2>=AI16,1,0) | AN16: =AN15+1 | AO16: Remove the evaporator cover (9) from HVAC unit using suitable lifting device. (None) | AP16: =IF($AQ$2>=AN16,1,0) | AS16: =AS15+1 | AT16: Replace the plugs (Visual Inspection) | AU16: =IF($AV$2>=AS16,1,0) | AX16: =AX15+1 | AY16: Replace with new SAT Sensor (None) | AZ16: =IF($BA$2>=AX16,1,0) | BC16: =BC15+1 | BD16: Tighten the fastener of RAT (Spanner) | BE16: =IF(BF$2>=BC16,1,0) | BH16: =BH15+1 | BI16: Close electrical control panel assembly (None) | BJ16: =IF($BK$2>=BH16,1,0) | BM16: =BM15+1 | BN16: Clean Smoke Detector (Bristle Brush) | BO16: =IF($BP$2>=BM16,1,0) | BR16: =BR15+1 | BS16: Compressor Cover Removal (None) | BT16: =IF($BU$2>=BR16,1,0)
B17: RAT Sensor | E17: =E16+1 | F17: Open supply air cover (Spanner) | G17: =IF($H$2>=E17,1,0) | J17: =J16+1 | K17: Open supply air blower (Spanner) | L17: =IF($M$2>=J17,1,0) | O17: =O16+1 | P17: Remove bottom panel (Insulated Gloves) | Q17: =IF($R$2>=O17,1,0) | T17: =T16+1 | U17: Place the hose inside the hole and use high pressure to remove the debris from the drain hole. (None) | V17: =IF($W$2>=T17,1,0) | Y17: =Y16+1 | Z17: Check temperature of solenoid valve using clamp thermometer (Clamp Thermometer) | AA17: =IF($AB$2>=Y17,1,0) | AD17: =AD16+1 | AE17: Remove the condenser coil cover (Lifting Device) | AF17: =IF($AG$2>=AD17,1,0) | AI17: =AI16+1 | AJ17: Unscrew bolt compressor unit cover (Spanner) | AK17: =IF($AL$2>=AI17,1,0) | AN17: =AN16+1 | AO17: Remove Heat bank screws (Spanner) | AP17: =IF($AQ$2>=AN17,1,0) | AS17: =AS16+1 | AT17: Tighten loose connection of circuit breakers (Screwdriver) | AU17: =IF($AV$2>=AS17,1,0) | AX17: =AX16+1 | AY17: Secure with SAT Bolt (None) | AZ17: =IF($BA$2>=AX17,1,0) | BC17: =BC16+1 | BD17: Check working (Visual Inspection) | BE17: =IF(BF$2>=BC17,1,0) | BH17: =BH16+1 | BI17: DB9 Connection Clarification Pending (None) | BJ17: =IF($BK$2>=BH17,1,0) | BM17: =BM16+1 | BN17: Remove Smoke Detector Bolts (Spanner) | BO17: =IF($BP$2>=BM17,1,0) | BR17: =BR16+1 | BS17: Check hp lp pressure using manifold gauge set (None) | BT17: =IF($BU$2>=BR17,1,0)
B18: Evaporator Coil | E18: =E17+1 | F18: Clean the supply air cover (1) with compressed air. (Compressed Air Gun) | G18: =IF($H$2>=E18,1,0) | J18: =J17+1 | K18: Clean the supply air blower (1) with compressed air. (Compressed Air Gun) | L18: =IF($M$2>=J18,1,0) | O18: =O17+1 | P18: Unscrew return air damper (Spanner) | Q18: =IF($R$2>=O18,1,0) | T18: =T17+1 | U18: Ensure that draining is done completely through the drain tube (3). (Compressed Air Gun) | V18: =IF($W$2>=T18,1,0) | Y18: =Y17+1 | Z18: Unscrew solenoid valve using spanner (Spanner) | AA18: =IF($AB$2>=Y18,1,0) | AD18: =AD17+1 | AE18: Clean condenser coil (Bristle Brush) | AF18: =IF($AG$2>=AD18,1,0) | AI18: =AI17+1 | AJ18: Compressor Cover Removal (None) | AK18: =IF($AL$2>=AI18,1,0) | AN18: =AN17+1 | AO18: Remove Heat bank assembly (Insulated Gloves) | AP18: =IF($AQ$2>=AN18,1,0) | AS18: =AS17+1 | AT18: Circuit Breaker Cleaning (Bristle Brush) | AU18: =IF($AV$2>=AS18,1,0) | AX18: =AX17+1 | AY18: Unbolt the return air temperature sensor (Spanner) | AZ18: =IF($BA$2>=AX18,1,0) | BH18: =BH17+1 | BI18: Remove Converter Bolts (Spanner) | BJ18: =IF($BK$2>=BH18,1,0) | BM18: =BM17+1 | BN18: Remove Smoke Detector unit (Visual Inspection) | BO18: =IF($BP$2>=BM18,1,0) | BR18: =BR17+1 | BS18: Unscrew compressor bolt (Spanner) | BT18: =IF($BU$2>=BR18,1,0)
B19: Condensor Coil | E19: =E18+1 | F19: Rotate supply air cover (1) motor with hand and ensure that only a light force is required to rotate it. (Insulated Hand Gloves) | G19: =IF($H$2>=E19,1,0) | J19: =J18+1 | K19: Rotate supply air blower (1) motor with hand and ensure that only a light force is required to rotate it. (Insulated Hand Gloves) | L19: =IF($M$2>=J19,1,0) | O19: =O18+1 | P19: Remove return air damper (Insulated Gloves) | Q19: =IF($R$2>=O19,1,0) | T19: =T18+1 | U19: Check for leaks in TX Valve (Electronic Leak Detector) | V19: =IF($W$2>=T19,1,0) | Y19: =Y18+1 | Z19: Remove solenoid valve (Visual Inspection) | AA19: =IF($AB$2>=Y19,1,0) | AD19: =AD18+1 | AE19: Straighten any bent fins with a fin comb (Fin Comb) | AF19: =IF($AG$2>=AD19,1,0) | AI19: =AI18+1 | AJ19: Clean the dust on the component with a soft bristle brush (with the metal part insulated) (Bristle Brush) | AK19: =IF($AL$2>=AI19,1,0) | AN19: =AN18+1 | AO19: Replace Heat bank assembly (None) | AP19: =IF($AQ$2>=AN19,1,0) | AS19: =AS18+1 | AT19: Close electrical control panel assembly (None) | AU19: =IF($AV$2>=AS19,1,0) | AX19: =AX18+1 | AY19: Remove the return air temperature sensor (None) | AZ19: =IF($BA$2>=AX19,1,0) | BH19: =BH18+1 | BI19: Converter Removal (Lifting Device) | BJ19: =IF($BK$2>=BH19,1,0) | BM19: =BM18+1 | BN19: Replace Smoke Detector unit (Visual Inspection) | BO19: =IF($BP$2>=BM19,1,0) | BR19: =BR18+1 | BS19: Remove the compressor (Insulated Gloves) | BT19: =IF($BU$2>=BR19,1,0)
B20: Solenoid Valve | E20: =E19+1 | F20: Remove supply air blower (Screwdriver) | G20: =IF($H$2>=E20,1,0) | J20: =J19+1 | K20: Remove supply air blower (Screwdriver) | L20: =IF($M$2>=J20,1,0) | O20: =O19+1 | P20: Check moisture indicator on the sight glass (1) to find any excessive moisture in the system. (Electronic Leak Detector) | Q20: =IF($R$2>=O20,1,0) | T20: =T19+1 | U20: Fix TX valve with spanner (Spanner) | V20: =IF($W$2>=T20,1,0) | Y20: =Y19+1 | Z20: Replace solenoid valve (Visual Inspection) | AA20: =IF($AB$2>=Y20,1,0) | AD20: =AD19+1 | AE20: Clean the coil with compressed air (Compressed Air) | AF20: =IF($AG$2>=AD20,1,0) | AI20: =AI19+1 | AJ20: Ensure compressor is not over heated (Clamp Thermometer) | AK20: =IF($AL$2>=AI20,1,0) | AN20: =AN19+1 | AO20: Use a fin comb to straighten any bent fins. (Fin Comb) | AP20: =IF($AQ$2>=AN20,1,0) | AS20: =AS19+1 | AT20: Check Heat Bank (Clamp Thermometer) | AU20: =IF($AV$2>=AS20,1,0) | AX20: =AX19+1 | AY20: Replace the return air temperature sensor (None) | AZ20: =IF($BA$2>=AX20,1,0) | BC20: Sr. No. | BD20: Components Affected | BH20: =BH19+1 | BI20: Check for short circuit using multimeter (Visual Inspection) | BJ20: =IF($BK$2>=BH20,1,0) | BM20: =BM19+1 | BN20: Secure Smoke Detector Bolts (None) | BO20: =IF($BP$2>=BM20,1,0) | BR20: =BR19+1 | BS20: Replace the compressor (None) | BT20: =IF($BU$2>=BR20,1,0)
B21: Heater | E21: =E20+1 | F21: Replace supply air blower (Visual Inspection) | G21: =IF($H$2>=E21,1,0) | J21: =J20+1 | K21: Replace supply air blower (Visual Inspection) | L21: =IF($M$2>=J21,1,0) | O21: =O20+1 | P21: Locate the leak (Spanner) | Q21: =IF($R$2>=O21,1,0) | T21: =T20+1 | U21: Remove TX valve if necessary (Visual Inspection) | V21: =IF($W$2>=T21,1,0) | Y21: =Y20+1 | Z21: Screw solenoid valve using spanner (Visual Inspection) | AA21: =IF($AB$2>=Y21,1,0) | AD21: =AD20+1 | AE21: Loosen and remove 24 nos M8X20 bolts (8) along with washer set (7) to open evaporator cover (9). (Spanner) | AF21: =IF($AG$2>=AD21,1,0) | AI21: =AI20+1 | AJ21: Unscrew Fan bolt (Spanner) | AK21: =IF($AL$2>=AI21,1,0) | AN21: =AN20+1 | AO21: Wash the evaporator coil (1) with warm to hot water and a small quantity of detergent. The hot water softens the bristles helps the grease to dissolve and removes the chlorides. (Bristle Brush) | AP21: =IF($AQ$2>=AN21,1,0) | AS21: =AS20+1 | AT21: Heat bank damaged (None) | AU21: =IF($AV$2>=AS21,1,0) | AX21: =AX20+1 | AY21: Secure the RAT sensor bolt (None) | AZ21: =IF($BA$2>=AX21,1,0) | BC21: 1 | BD21: RAT Sensor | BE21: =IF(BE11=1,0,1) | BF21: Open: 1, Close: 0 | BH21: =BH20+1 | BI21: Put converter back to it place (Visual Inspection) | BJ21: =IF($BK$2>=BH21,1,0) | BM21: =BM20+1 | BN21: Check working (Visual Inspection) | BO21: =IF($BP$2>=BM21,1,0) | BR21: =BR20+1 | BS21: Compressor Cover close (None) | BT21: =IF($BU$2>=BR21,1,0)
B22: Electrical Connections | E22: =E21+1 | F22: Check working (Visual Inspection) | G22: =IF($H$2>=E22,1,0) | J22: =J21+1 | K22: Close air supply blower (Visual Inspection) | L22: =IF($M$2>=J22,1,0) | O22: =O21+1 | P22: Repair the leak (None) | Q22: =IF($R$2>=O22,1,0) | T22: =T21+1 | U22: Replace TX valve if necessary (Visual Inspection) | V22: =IF($W$2>=T22,1,0) | Y22: =Y21+1 | Z22: Check HVAC working (Visual Inspection) | AA22: =IF($AB$2>=Y22,1,0) | AD22: =AD21+1 | AE22: Remove hinge pins to remove the evaporator cover (9) from HVAC unit. (Pliers) | AF22: =IF($AG$2>=AD22,1,0) | AI22: =AI21+1 | AJ22: Open fan cover (Insulated Gloves) | AK22: =IF($AL$2>=AI22,1,0) | AN22: =AN21+1 | AO22: Clean the drain tray (2) with wet cloth (Wet Cloth) | AP22: =IF($AQ$2>=AN22,1,0) | AS22: =AS21+1 | AT22: Remove Heat bank screws (Spanner) | AU22: =IF($AV$2>=AS22,1,0) | AX22: =AX21+1 | AY22: Tighten the fastener of RAT (Spanner) | AZ22: =IF($BA$2>=AX22,1,0) | BC22: 2 | BD22: HOT 1 Switch | BH22: =BH21+1 | BI22: Secure converter with bolts (Visual Inspection) | BJ22: =IF($BK$2>=BH22,1,0) | BR22: =BR21+1 | BS22: Screw bolt compressor unit cover (None) | BT22: =IF($BU$2>=BR22,1,0)
B23: Temperature Sensor | J23: =J22+1 | K23: Unscrew fresh air filter bolt (Screwdriver) | L23: =IF($M$2>=J23,1,0) | O23: =O22+1 | P23: Check working (Visual Inspection) | Q23: =IF($R$2>=O23,1,0) | T23: =T22+1 | U23: Check working (Visual Inspection) | V23: =IF($W$2>=T23,1,0) | AD23: =AD22+1 | AE23: Remove the evaporator cover (9) from HVAC unit using suitable lifting device. (None) | AF23: =IF($AG$2>=AD23,1,0) | AI23: =AI22+1 | AJ23: Unscrews Fan Motor Bolt (Spanner) | AK23: =IF($AL$2>=AI23,1,0) | AN23: =AN22+1 | AO23: Ensure that there is no condensate or debris left over on the drain tray (2). (Vacuum Cleaner) | AP23: =IF($AQ$2>=AN23,1,0) | AS23: =AS22+1 | AT23: Remove Heat bank assembly (Insulated Gloves) | AU23: =IF($AV$2>=AS23,1,0) | AX23: =AX22+1 | AY23: Check working (Visual Inspection) | AZ23: =IF($BA$2>=AX23,1,0) | BH23: =BH22+1 | BI23: Check working (Visual Inspection) | BJ23: =IF($BK$2>=BH23,1,0) | BR23: =BR22+1 | BS23: Loosen and remove 24 nos M8X20 bolts (8) along with washer set (7) to open evaporator cover (9). (Spanner) | BT23: =IF($BU$2>=BR23,1,0)
B24: RAT Sensor | J24: =J23+1 | K24: Replace fresh air filter (Visual Inspection) | L24: =IF($M$2>=J24,1,0) | AD24: =AD23+1 | AE24: Open supply air blower (Spanner) | AF24: =IF($AG$2>=AD24,1,0) | AI24: =AI23+1 | AJ24: Remove Fan Motor (Insulated Gloves) | AK24: =IF($AL$2>=AI24,1,0) | AN24: =AN23+1 | AO24: Remove the grommet on the drain hole cover. (Pliers) | AP24: =IF($AQ$2>=AN24,1,0) | AS24: =AS23+1 | AT24: Replace Heat bank assembly (None) | AU24: =IF($AV$2>=AS24,1,0) | BD24: Cause 1 & Rectified | BE24: =IF(AND(BE17=1,BF4=1),1,0) | BM24: Sr. No. | BN24: Components Affected | BR24: =BR23+1 | BS24: Remove hinge pins to remove the evaporator cover (9) from HVAC unit. (Pliers) | BT24: =IF($BU$2>=BR24,1,0)
B25: Smoke Detector | E25: Sr. No. | F25: Components Affected | G25: Status | H25: Remarks | J25: =J24+1 | K25: Clean the fresh air dampers (1) and damper motor (2) with dry compressed air. (Bristle Brush) | L25: =IF($M$2>=J25,1,0) | Y25: Sr. No. | Z25: Components Affected | AD25: =AD24+1 | AE25: Clean the supply air blower (1) with compressed air. (Compressed Air Gun) | AF25: =IF($AG$2>=AD25,1,0) | AI25: =AI24+1 | AJ25: Replace Fan Motor (None) | AK25: =IF($AL$2>=AI25,1,0) | AN25: =AN24+1 | AO25: Place the hose inside the hole and use high pressure to remove the debris from the drain hole. (None) | AP25: =IF($AQ$2>=AN25,1,0) | AS25: =AS24+1 | AT25: Clean Heat bank (Compressed Air Gun) | AU25: =IF($AV$2>=AS25,1,0) | BD25: Cause 2 & Rectified | BE25: =IF(AND(BE17=1,BF4=2),1,0) | BF25: Not present | BM25: 1 | BN25: Fresh Air Damper | BO25: =IF(BO11=1,0,1) | BP25: Open: 1, Close: 0 | BR25: =BR24+1 | BS25: Remove the evaporator cover (9) from HVAC unit using suitable lifting device. (None) | BT25: =IF($BU$2>=BR25,1,0)
E26: 1 | F26: Control Panel Circuit Breakers | G26: =IF(G3=1,0,IF(G11=1,0,1)) | H26: Open: 1, Close: 0 | J26: =J25+1 | K26: Remove the fresh air dampers (Spanner) | L26: =IF($M$2>=J26,1,0) | O26: Sr. No. | P26: Components Affected | T26: Sr. No. | U26: Components Affected | Y26: 1 | Z26: Filter Drier | AA26: =IF(AA11=1,0,1) | AB26: Open: 1, Close: 0 | AD26: =AD25+1 | AE26: Rotate supply air blower (1) motor with hand and ensure that only a light force is required to rotate it. (Insulated Hand Gloves) | AF26: =IF($AG$2>=AD26,1,0) | AI26: =AI25+1 | AJ26: Clean the condenser fan with dry compressed air (Compressed Air) | AK26: =IF($AL$2>=AI26,1,0) | AN26: =AN25+1 | AO26: Fix TX valve with spanner (Spanner) | AP26: =IF($AQ$2>=AN26,1,0) | AS26: =AS25+1 | AT26: Unbolt the return air temperature sensor (Spanner) | AU26: =IF($AV$2>=AS26,1,0) | AX26: Sr. No. | AY26: Components Affected | BD26: Fault Reset Logic | BE26: =IF(OR(BE24:BE25),1,0) | BH26: Sr. No. | BI26: Components Affected | BM26: 2 | BN26: Smoke Detector | BR26: =BR25+1 | BS26: Remove electrical control panel assembly (Spanner) | BT26: =IF($BU$2>=BR26,1,0)
E27: =E26+1 | F27: Supply Air Blower | G27: =IF(OR(G3:G4),0,1) | J27: =J26+1 | K27: Replace the fresh air dampers (Visual Inspection) | L27: =IF($M$2>=J27,1,0) | O27: 1 | P27: Supply Air Filter | Q27: =IF(Q11=1,0,1) | R27: Open: 1, Close: 0 | T27: 1 | U27: Evaporator Coil Damage | V27: =IF(V11=1,0,1) | W27: Open: 1, Close: 0 | Y27: 2 | Z27: Piping Section | AD27: =AD26+1 | AE27: Remove supply air blower (Screwdriver) | AF27: =IF($AG$2>=AD27,1,0) | AI27: =AI26+1 | AJ27: Unscrew condenser fan bolt (Spanner) | AK27: =IF($AL$2>=AI27,1,0) | AN27: =AN26+1 | AO27: Remove TX valve if necessary (Visual Inspection) | AP27: =IF($AQ$2>=AN27,1,0) | AS27: =AS26+1 | AT27: Remove the return air temperature sensor (None) | AU27: =IF($AV$2>=AS27,1,0) | AX27: 1 | AY27: Temperature Sensor | AZ27: =IF(AZ11=1,0,1) | BA27: Open: 1, Close: 0 | BH27: 1 | BI27: Electrical Connections | BJ27: =IF(BJ11=1,0,1) | BK27: Open: 1, Close: 0 | BR27: =BR26+1 | BS27: Check all circuit breakers and close. (Multimeter) | BT27: =IF($BU$2>=BR27,1,0)
J28: =J27+1 | K28: Remove fresh air damper motor (Screwdriver) | L28: =IF($M$2>=J28,1,0) | O28: =O27+1 | P28: Supply Air Blower | T28: 2 | U28: TX Valve | AD28: =AD27+1 | AE28: Replace supply air blower (Visual Inspection) | AF28: =IF($AG$2>=AD28,1,0) | AI28: =AI27+1 | AJ28: Remove condenser fan (Insulated Gloves) | AK28: =IF($AL$2>=AI28,1,0) | AN28: =AN27+1 | AO28: Replace TX valve if necessary (Visual Inspection) | AP28: =IF($AQ$2>=AN28,1,0) | AS28: =AS27+1 | AT28: Replace the return air temperature sensor (None) | AU28: =IF($AV$2>=AS28,1,0) | BN28: Cause 1 & Rectified | BO28: =IF(AND(BO15=1,BP4=1),1,0) | BR28: =BR27+1 | BS28: Unplug the connected wires (Screwdriver) | BT28: =IF($BU$2>=BR28,1,0)
F29: Cause 1 & Rectified | G29: =IF(AND(H4=1,G11=1),1,0) | J29: =J28+1 | K29: Replace fresh air damper motor (Visual Inspection) | L29: =IF($M$2>=J29,1,0) | O29: =O28+1 | P29: Refrigerent Level | AD29: =AD28+1 | AE29: Close air supply blower (Visual Inspection) | AF29: =IF($AG$2>=AD29,1,0) | AI29: =AI28+1 | AJ29: Replace condenser fan (None) | AK29: =IF($AL$2>=AI29,1,0) | AN29: =AN28+1 | AO29: Remove the condenser coil cover (Lifting Device) | AP29: =IF($AQ$2>=AN29,1,0) | AS29: =AS28+1 | AT29: Bolt the RAT (None) | AU29: =IF($AV$2>=AS29,1,0) | AY29: Cause 1 & Rectified | AZ29: =IF(AND(AZ23=1,$BA$4=1),1,0) | BI29: Cause 1 & Rectified | BJ29: =IF(AND(BJ23=1,$BK$4=1),1,0) | BN29: Cause 2 & Rectified | BO29: =IF(AND(BO21=1,BP8=2),1,0) | BR29: =BR28+1 | BS29: Remove electrical plugs. (Insulated Gloves) | BT29: =IF($BU$2>=BR29,1,0)
F30: Cause 2 & Rectified | G30: =IF(AND(H4=2,G22=1),1,0) | J30: =J29+1 | K30: Check working (Visual Inspection) | L30: =IF($M$2>=J30,1,0) | Z30: Cause 1 & Rectified | AA30: =IF(AND(AA12=1,AB4=1),1,0) | AD30: =AD29+1 | AE30: Unscrew bottom panel (Spanner) | AF30: =IF($AG$2>=AD30,1,0) | AI30: =AI29+1 | AJ30: Remove the condenser coil cover (Lifting Device) | AK30: =IF($AL$2>=AI30,1,0) | AN30: =AN29+1 | AO30: Clean condenser coil (Bristle Brush) | AP30: =IF($AQ$2>=AN30,1,0) | AS30: =AS29+1 | AT30: Check working (Visual Inspection) | AU30: =IF($AV$2>=AS30,1,0) | AY30: Fault Reset Logic | AZ30: =IF(OR(AZ29),1,0) | BI30: Fault Reset Logic | BJ30: =IF(OR(BJ29),1,0) | BN30: Fault Reset Logic | BO30: =IF(OR(BO28:BO29),1,0) | BR30: =BR29+1 | BS30: Replace the plugs (Visual Inspection) | BT30: =IF($BU$2>=BR30,1,0)
F31: Fault Reset Logic | G31: =IF(OR(G29:G30),1,0) | H31: 1: Reset | P31: Cause 1 & Rectified | Q31: =IF(AND(Q15=1,R4=1),1,0) | U31: Cause 1 & Rectified | V31: =IF(AND(V11=1,W4=1),1,0) | Z31: Cause 2 & Rectified | AA31: =IF(AND(AA22=1,AB4=2),1,0) | AD31: =AD30+1 | AE31: Remove bottom panel (Insulated Gloves) | AF31: =IF($AG$2>=AD31,1,0) | AI31: =AI30+1 | AJ31: Clean condenser coil (Bristle Brush) | AK31: =IF($AL$2>=AI31,1,0) | AN31: =AN30+1 | AO31: Straighten any bent fins with a fin comb (Fin Comb) | AP31: =IF($AQ$2>=AN31,1,0) | BR31: =BR30+1 | BS31: Connect the electrical plugs. (Screwdriver) | BT31: =IF($BU$2>=BR31,1,0)
P32: Cause 2 & Rectified | Q32: =IF(AND(Q15=1,R4=2),1,0) | U32: Cause 2 & Rectified | V32: =IF(AND(V23=1,W4=2),1,0) | Z32: Fault Reset Logic | AA32: =IF(OR(AA30:AA31),1,0) | AD32: =AD31+1 | AE32: Unscrew return air damper (Spanner) | AF32: =IF($AG$2>=AD32,1,0) | AI32: =AI31+1 | AJ32: Straighten any bent fins with a fin comb (Fin Comb) | AK32: =IF($AL$2>=AI32,1,0) | AN32: =AN31+1 | AO32: Clean the coil with compressed air (Compressed Air) | AP32: =IF($AQ$2>=AN32,1,0) | BR32: =BR31+1 | BS32: Close electrical control panel assembly (None) | BT32: =IF($BU$2>=BR32,1,0)
J33: Sr. No. | K33: Components Affected | P33: Cause 3 & Rectified | Q33: =IF(AND(R4=3,Q23=1),1,0) | U33: Fault Reset Logic | V33: =IF(OR(V31:V32),1,0) | AD33: =AD32+1 | AE33: Remove return air damper (Insulated Gloves) | AF33: =IF($AG$2>=AD33,1,0) | AI33: =AI32+1 | AJ33: Clean the coil with compressed air (Compressed Air) | AK33: =IF($AL$2>=AI33,1,0) | AN33: =AN32+1 | AO33: Close HVAC components (None) | AP33: =IF($AQ$2>=AN33,1,0) | AS33: Sr. No. | AT33: Components Affected | BR33: =BR32+1 | BS33: Remove Heat bank screws (Spanner) | BT33: =IF($BU$2>=BR33,1,0)
J34: 1 | K34: Air Blower Circuit Breakers | L34: =IF(OR(L11=1,L3=1),0,1) | M34: Open: 1, Close: 0 | P34: Fault Reset Logic | Q34: =IF(OR(Q31:Q33),1,0) | AD34: =AD33+1 | AE34: Check moisture indicator on the sight glass (1) to find any excessive moisture in the system. (Electronic Leak Detector) | AF34: =IF($AG$2>=AD34,1,0) | AI34: =AI33+1 | AJ34: Loosen and remove 24 nos M8X20 bolts (8) along with washer set (7) to open evaporator cover (9). (Spanner) | AK34: =IF($AL$2>=AI34,1,0) | AN34: =AN33+1 | AO34: Unscrew bolt compressor unit cover (Spanner) | AP34: =IF($AQ$2>=AN34,1,0) | AS34: 1 | AT34: Heater Circuit Breaker | AU34: =IF(AU13=1,0,1) | AV34: Open: 1, Close: 0 | BR34: =BR33+1 | BS34: Remove Heat bank assembly (Insulated Gloves) | BT34: =IF($BU$2>=BR34,1,0)
J35: =J34+1 | K35: Supply Air Blower | L35: =IF(OR(L3:L4),0,1) | AD35: =AD34+1 | AE35: Locate the leak and repair (Spanner) | AF35: =IF($AG$2>=AD35,1,0) | AI35: =AI34+1 | AJ35: Remove hinge pins to remove the evaporator cover (9) from HVAC unit. (Pliers) | AK35: =IF($AL$2>=AI35,1,0) | AN35: =AN34+1 | AO35: Compressor Cover Removal (None) | AP35: =IF($AQ$2>=AN35,1,0) | AS35: 2 | AT35: Heater | BR35: =BR34+1 | BS35: Replace Heat bank assembly (None) | BT35: =IF($BU$2>=BR35,1,0)
J36: =J35+1 | K36: Fresh Air Damper | AD36: =AD35+1 | AE36: Check working (Visual Inspection) | AF36: =IF($AG$2>=AD36,1,0) | AI36: =AI35+1 | AJ36: Remove the evaporator cover (9) from HVAC unit using suitable lifting device. (None) | AK36: =IF($AL$2>=AI36,1,0) | AN36: =AN35+1 | AO36: Check compressor of excessive noise or leaks (None) | AP36: =IF($AQ$2>=AN36,1,0) | AS36: 3 | AT36: RAT Sensor | BR36: =BR35+1 | BS36: Clean Heat bank (Compressed Air Gun) | BT36: =IF($BU$2>=BR36,1,0)
AI37: =AI36+1 | AJ37: Open supply air blower (Spanner) | AK37: =IF($AL$2>=AI37,1,0) | AN37: =AN36+1 | AO37: Unscrew compressor bolt (Spanner) | AP37: =IF($AQ$2>=AN37,1,0) | AS37: 4 | AT37: Heater Circuit Breaker Manual Reset Required | BR37: =BR36+1 | BS37: Secure the Heat bank screws (None) | BT37: =IF($BU$2>=BR37,1,0)
K38: Cause 1 & Rectified | L38: =IF(AND(L11=1,M4=1),1,0) | AI38: =AI37+1 | AJ38: Clean the supply air blower (1) with compressed air. (Compressed Air Gun) | AK38: =IF($AL$2>=AI38,1,0) | AN38: =AN37+1 | AO38: Remove the compressor (Insulated Gloves) | AP38: =IF($AQ$2>=AN38,1,0) | AS38: 5 | AT38: Electrical Connections | BR38: =BR37+1 | BS38: Run HVAC 20 mins. (None) | BT38: =IF($BU$2>=BR38,1,0)
K39: Cause 2 & Rectified | L39: =IF(AND(L16=1,M4=2),1,0) | AD39: Sr. No. | AE39: Components Affected | AI39: =AI38+1 | AJ39: Rotate supply air blower (1) motor with hand and ensure that only a light force is required to rotate it. (Insulated Hand Gloves) | AK39: =IF($AL$2>=AI39,1,0) | AN39: =AN38+1 | AO39: Replace the compressor (None) | AP39: =IF($AQ$2>=AN39,1,0) | BR39: =BR38+1 | BS39: Unusual noise from compressor assembly (None) | BT39: =IF($BU$2>=BR39,1,0)
K40: Cause 3 & Rectified | L40: =IF(AND(M4=3,L30=1),1,0) | AD40: 1 | AE40: Condensor Fan Motor | AF40: =IF(AF12=1,0,1) | AG40: Open: 1, Close: 0 | AI40: =AI39+1 | AJ40: Remove supply air blower (Screwdriver) | AK40: =IF($AL$2>=AI40,1,0) | AN40: =AN39+1 | AO40: Check hp lp pressure using manifold gauge set (None) | AP40: =IF($AQ$2>=AN40,1,0) | AT40: Cause 1 & Rectified | AU40: =IF(AND(AU19=1,$AV$4=1),1,0) | BR40: =BR39+1 | BS40: Unscrew bolt compressor unit cover (Spanner) | BT40: =IF($BU$2>=BR40,1,0)
...

Sheet Calculation
A1: Inputs | I1: Sr. No | J1: Item | K1: Heat Load (W) | L1: Qty | M1: Total Heat Load (W)
A2: c | B2: 1 | C2: KJ/Kg | E2: Outputs | I2: 1 | J2: Passenger | K2: 72.84 | L2: 340 | M2: =K2*L2
A3: Set Point | B3: ='LFD OLD'!F5+273 | C3: K | E3: Return Air | F3: =B18-J32 | G3: C | I3: 2 | J3: Solar Gain | K3: 2336 | L3: 1 | M3: =K3*L3
A4: Ambient Temp | B4: ='LFD OLD'!F7+273 | C4: K | I4: 3 | J4: Transmission Gain | K4: 2882 | L4: 1 | M4: =K4*L4
A5: Supply Temp | B5: ='LFD OLD'!F8+273 | C5: K | I5: 4 | J5: Internal Equipment | K5: 2500 | L5: 1 | M5: =K5*L5
A6: Time | B6: 0.8 | C6: s | E6: Supply Air Temp | F6: =IF(B14=1,(F3+B3-273)/2,F3) | I6: 5 | J6: Fan Motor Load | K6: 4000 | L6: 1 | M6: =K6*L6
A7: Loading | B7: ='DATA TRANSFER'!F40 | C7: pax | I7: 6 | J7: Fresh Air Load | K7: 6663 | L7: 1 | M7: =K7*L7
A8: Heat Load Damper | B8: 0.8 | C8: 0-1 | E8: Damper Pos | F8: =B7*25+25*IF('DATA TRANSFER'!CP18=1,0,1)*IF('DATA TRANSFER'!AE22=0,0,1) | I8: 7 | J8: Door Opening Load | K8: 525 | L8: 1 | M8: =K8*L8
A9: Comp 1 | B9: ='Mode Logic'!L18 | C9: On/off | F9: =IF('DATA TRANSFER'!AE24=1,100,Calculation!F8) | L9: Total Heat Load | M9: =SUM(M2:M8) | N9: W
A10: Comp 2 | B10: ='Mode Logic'!M18 | C10: On/off | D10: HVAC 1 DMA | N10: =M9/1000
A11: Comp 3 | B11: ='Mode Logic'!N18 | C11: On/off
A12: Comp 4 | B12: ='Mode Logic'!O18 | C12: On/off | I12: Fresh Air Load
A13: Heater | B13: ='DATA TRANSFER'!M24 | C13: On/off | I13: Air Flow | J13: =IF(B17=1,3037,0)/3600 | K13: m^3/s
A14: FAD | B14: ='DATA TRANSFER'!M16 | I14: Delta T | J14: =B9-B7 | K14: K
A15: Cooling | B15: =IF(AND(B9:B12),47,IF(OR(B9:B12),10,IF(B13=1,-9,0))) | C15: KW | E15: =MAX(IF(TCMS!D24>0,Calculation!O40+TCMS!D24,O40),'Set point Calc'!J14)
B16: =B15*1000 | C16: W | I16: Heat Load | J16: =J13*J14 | K16: KW
J17: =J16*1000 | K17: W
A18: Internal Temp(RAT) | B18: ='DATA TRANSFER'!F38 | C18: C | L18: ='Mode Logic'!M18
A19: Time Elapsed since Preconditioning | B19: ='DATA TRANSFER'!F36 | C19: mins | D19: Need to add timer start once preconditioning is triggered | I19: Total Heat Load
I20: 1 | J20: Heat Load | K20: =M9 | L20: W
I21: 2 | J21: Freah Air | K21: =J17*G8/100 | L21: W
I22: 3 | J22: Operational | L22: W
A23: Comp 1 | B23: ='DATA TRANSFER'!M41 | C23: On/off | I23: Total Heat Load | K23: =SUM(K20:K22)
A24: Comp 2 | B24: ='DATA TRANSFER'!M42 | C24: On/off | D24: HVAC 1 DMB
A25: Comp 3 | B25: ='DATA TRANSFER'!M43 | C25: On/off
A26: Comp 4 | B26: ='DATA TRANSFER'!M46 | C26: On/off | I26: Change in Temp
A27: Heater | B27: 1 | C27: On/off | I27: 1 | J27: Delta W | K27: =B16-K23 | L27: W
A28: FAD | B28: 1 | I28: 2 | J28: Time | K28: =B6 | L28: s | N28: DM1 HVAC1
A29: Cooling | B29: =IF(AND(B23:B26),47,IF(OR(B23:B26),10,IF(B27=1,-9,0))) | C29: KW | I29: 3 | J29: c | K29: 1 | L29: Kj/Kg.K
B30: =B29*1000 | C30: W | I30: 4 | J30: m | K30: 1000 | L30: Kg
B32: DMA | C32: TCA | D32: DMB | I32: Change | J32: =(1/1000)*(K27*K28)/(K29*K30) | K32: C
A33: Set Point | B33: =MAX(IF(TCMS!D24>0,Calculation!O40+TCMS!D24,O40),'Set point Calc'!J14) | C33: =IF(TCMS!E24>0,Calculation!P40+TCMS!E24,P40) | D33: =IF(TCMS!F24>0,Calculation!Q40+TCMS!F24,Q40)
A34: Ambient Temp | B34: ='DATA TRANSFER'!F39 | C34: =B34 | D34: =C34
A35: RAT | B35: ='DATA TRANSFER'!Q584 | C35: ='DATA TRANSFER'!G38 | D35: ='DATA TRANSFER'!H38 | I35: Change in Temp
A36: New RAT | B36: =B35-B90 | C36: =C35-C90 | D36: =D35-B90 | I36: 1 | J36: Delta W | K36: =B15-K23 | L36: W
I37: 2 | J37: Time | K37: =B15 | L37: s | N37: DM1 HVAC2
A38: Pre-Cool | B38: =IF('Mode Logic'!B27=1,1,0) | C38: =B38 | D38: =C38 | E38: =IF(B48=1,0,IF(OR(B38=1,B39=1,B40=1),0,IF('Mode Logic'!B30=1,1,0)))*IF(B50=1,0,1) | F38: ='DATA TRANSFER'!F38 | I38: 3 | J38: c | K38: 1 | L38: Kj/Kg.K
A39: Pre-heat | B39: =IF('Mode Logic'!B26=1,1,0) | C39: =B39 | D39: =C39 | I39: 4 | J39: m | K39: 1000 | L39: Kg
A40: Auto Cool 1 (Cooling Circuits Disabled) | B40: =IF(B48=1,0,IF(B38=0,IF('Mode Logic'!B29=1,1,0)))*IF(B50=1,0,1) | C40: =B40 | D40: =IF(OR(D48=0,D38=0,D50=0),1,IF(AND(D35>=D33+1.5,D35<D33+2.5),1,0)) | E40: FAT<T4 | G40: =IF(OR(B48=0,B38=0,B50=0),1,IF(AND(B35>=B33+1.5,B35<B33+2.5),1,0))
A41: Auto Cool 2 | B41: =IF(B48=1,0,IF(OR(B38=1,B39=1,B40=1),0,IF('Mode Logic'!B30=1,1,0)))*IF(B50=1,0,1) | C41: =B41 | D41: =IF(OR(D48=1,D38=1,D50=1),0,IF(AND(D35>=D33,D35<D33+1),1,0)) | I41: Change | J41: =(1/1000)*(K36*K37)/(K38*K39) | K41: C
...

Sheet Calc again
A1: Inputs | I1: Sr. No | J1: Item | K1: Heat Load (W) | L1: Qty | M1: Total Heat Load (W)
E2: Outputs | I2: 1 | J2: Passenger | K2: 72.84 | L2: 340 | M2: =K2*L2
A3: Set Point | B3: =Calculation!B33+273 | C3: K | E3: Return Air | F3: =B18-J32 | G3: C | I3: 2 | J3: Solar Gain | K3: 2336 | L3: 1 | M3: =K3*L3
A4: Ambient Temp | B4: =Calculation!B34+273 | C4: K | I4: 3 | J4: Transmission Gain | K4: 2882 | L4: 1 | M4: =K4*L4
A5: Supply Temp | B5: ='DATA TRANSFER'!F39+273 | C5: K | I5: 4 | J5: Internal Equipment | K5: 2500 | L5: 1 | M5: =K5*L5
A6: Time | B6: 0.8 | C6: s | E6: Supply Air Temp | F6: =IF(B14=1,(F3+B3-273)/2,F3) | I6: 5 | J6: Fan Motor Load | K6: 4000 | L6: 1 | M6: =K6*L6
A7: Loading | B7: =MAX(D13:D16) | C7: pax | I7: 6 | J7: Fresh Air Load | K7: 6663 | L7: 1 | M7: =K7*L7
A8: Heat Load Damper | B8: =IF(B7=0,0.8,IF(B7=1,0.7,IF(B7=2,0.5,0.45))) | C8: 0-1 | E8: Damper Pos | F8: ='DATA TRANSFER'!AE13 | I8: 7 | J8: Door Opening Load | K8: 525 | L8: 1 | M8: =K8*L8
A9: Comp 1 | B9: ='Mode Logic'!L18 | C9: On/off | F9: =IF('DATA TRANSFER'!AE24=1,100,Calculation!F8) | L9: Total Heat Load | M9: =SUM(M2:M8) | N9: W
A10: Comp 2 | B10: ='Mode Logic'!M18 | C10: On/off | D10: HVAC 1 DMA | N10: =M9/1000
A11: Comp 3 | B11: ='Mode Logic'!N18 | C11: On/off
A12: Comp 4 | B12: ='Mode Logic'!O18 | C12: On/off | D12: Status | E12: Loading | F12: Number of Passenger | G12: Design Heat Load (kW) | I12: Fresh Air Load
A13: Heater 1 | B13: ='DATA TRANSFER'!M24 | C13: On/off | D13: =IF(AND('DATA TRANSFER'!F40<=100,'DATA TRANSFER'!F40>81),4,0) | E13: AW0 | F13: 340 | G13: 88.7 | I13: Air Flow | J13: =IF(B17=1,3037,0)/3600 | K13: m^3/s
A14: FAD | B14: ='DATA TRANSFER'!M16 | D14: =IF(AND('DATA TRANSFER'!F40<=81,'DATA TRANSFER'!F40>59),3,0) | E14: AW1 | F14: 274 | G14: 73.9 | I14: Delta T | J14: =B9-B7 | K14: K
A15: Cooling | B15: =IF(AND(B9:B12),47,IF(OR(B9:B12),10,IF(B13=1,-9,0))) | C15: KW | D15: =IF(AND('DATA TRANSFER'!F40<=59,'DATA TRANSFER'!F40>15),2,0) | E15: AW2 | F15: 200 | G15: 57.7
A16: Cooling | B16: =B15*1000 | C16: W | D16: =IF('DATA TRANSFER'!F40<=15,1,0) | E16: AW3 | F16: 52 | G16: 27 | I16: Heat Load | J16: =J13*J14 | K16: KW
A17: Heater 2 | B17: ='DATA TRANSFER'!M30 | J17: =J16*1000 | K17: W
A18: Internal Temp(RAT) | B18: ='DATA TRANSFER'!F38 | C18: C | L18: ='Mode Logic'!M18
A19: Time Elapsed since Preconditioning | B19: ='DATA TRANSFER'!F36 | C19: mins | I19: Total Heat Load
A20: Number of Compressors ON | B20: =SUM(B9:B12) | I20: 1 | J20: Heat Load | K20: =M9 | L20: W
I21: 2 | J21: Freah Air | K21: =J17*G8/100 | L21: W
I22: 3 | J22: Operational | L22: W
A23: Comp 1 | B23: ='DATA TRANSFER'!M41 | C23: On/off | I23: Total Heat Load | K23: =SUM(K20:K22)
A24: Comp 2 | B24: ='DATA TRANSFER'!M42 | C24: On/off | D24: HVAC 1 DMB
A25: Comp 3 | B25: ='DATA TRANSFER'!M43 | C25: On/off
A26: Comp 4 | B26: ='DATA TRANSFER'!M46 | C26: On/off | I26: Change in Temp
A27: Heater | B27: 1 | C27: On/off | I27: 1 | J27: Delta W | K27: =B16-K23 | L27: W
